Workbook
Name HTML_Control: {"'단계별시설공사비'!$A$3:$K$51"}
Name HTML_Control: {"'단계별시설공사비'!$A$3:$K$51"}
Name HTML_Control: {"'단계별시설공사비'!$A$3:$K$51"}
Name 간이세액표: 간이세액표!$C$6:$N$652
Name 간이세액표: #REF!
Name 간이세액표: [2]간이세액표!$C$6:$N$652
Name 건강보험: 급여대장!$O$6:$O$10
Name 건강보험: [3]급여기준!$AO$5:$AO$91
Name 건강보험: #REF!
Name 건강정산: 급여대장!$U$6:$U$10
Name 건강정산: #REF!
Name 결근: [3]급여기준!$AQ$5:$AQ$91
Name 결근: [4]급여기준!$AQ$5:$AQ$108
Name 경영성과급: [3]급여기준!$AE$5:$AE$89
Name 경영성과급: [4]급여기준!$AE$5:$AE$106
Name 고용보험: 급여대장!$R$6:$R$10
Name 고용보험: [3]급여기준!$AM$5:$AM$91
Name 고용보험: #REF!
Name 고정연장근로수당: 급여대장!$I$6:$I$10
Name 고정연장근로수당: #REF!
Name 공제내역: [5]공제내역!$B$10:$N$49
Name 공제총액: [3]급여기준!$AS$5:$AS$91
Name 공제총액: [4]급여기준!$AS$5:$AS$108
Name 공제합계: 급여대장!$AB$6:$AB$10
Name 공제합계: #REF!
Name 과세_합계: 급여대장!$N$6:$N$10
Name 과세_합계: #REF!
Name 과표: SUM(#REF!)+MAX(0,#REF!-100000)+MAX(0,#REF!-200000)+MAX(0,#REF!-100000)
Name 국민연금: 급여대장!$Q$6:$Q$10
Name 국민연금: [3]급여기준!$AN$5:$AN$91
Name 국민연금: #REF!
Name 근로시간: #REF!
Name 급여_합계: 급여대장!$K$6:$K$10
Name 급여_합계: #REF!
Name 급여대장: [5]급여대장!$D$5:$AC$44
Name 기_본_급: 급여대장!$G$6:$G$10
Name 기_본_급: #REF!
Name 기본급: [3]급여기준!$U$5:$U$91
Name 기본급: [4]급여기준!$U$5:$U$108
Name 당직비: [3]급여기준!$W$5:$W$91
Name 당직비: [4]급여기준!$W$5:$W$108
Name 디비: [6]DB!$A:$N
Name ㅀ허ㅏㅏ: [7]기초데이타!$A$2:$A$763
Name 보험료범위: OFFSET(#REF!,,,COUNTA(#REF!)-2,7)
Name 보험요율: MAX((INDEX(보험료범위,,2)=#REF!)*(INDEX(보험료범위,,1)<=#REF!)*ROW(INDEX(보험료범위,,1)))
Name 보험요율: MAX((INDEX(보험료범위,,2)=#REF!)*(INDEX(보험료범위,,1)<=#REF!)*ROW(INDEX(보험료범위,,1)))
Name 보험적용: [8]기초데이타!#REF!
Name 보험정산: [3]급여기준!$AR$5:$AR$91
Name 보험정산: [4]급여기준!$AR$5:$AR$108
Name 사원명부: OFFSET(#REF!,,,MAX(#REF!))
Name 상여금: [3]급여기준!$AD$5:$AD$87
Name 상여금: [4]급여기준!$AD$5:$AD$105
Name 성명: 급여대장!$B$6:$B$10
Name 성명: [3]급여기준!$B$5:$B$91
Name 성명: #REF!
Name 성별: [3]급여기준!$F$5:$F$87
Name 성별: [4]급여기준!$F$5:$F$105
Name 소득세: 급여대장!$S$6:$S$10
Name 소득세: [3]급여기준!$AJ$5:$AJ$91
Name 소득세: #REF!

Sheet 급여셋팅
A1: 근로자 명부 작성
A2: 구분 | B2: 시업시각 | C2: 종업시각 | D2: 휴게시간 시작 | E2: 휴게시간 종료 | F2: 근로일 | G2: 휴일 | H2: 평일 근로시간 | I2: 연장 근로시간 | J2: 평일 야간 근로시간 | K2: 휴일 근로시간 | L2: 휴일 연장 근로시간 | M2: 휴일 야간 근로시간 | N2: 기본근로시간 | O2: 연장근로시간 | P2: 휴일근로시간 | Q2: 연차 | R2: 총 근로시간
A3: 본사 | B3: 0.375 | C3: 0.75 | D3: 0.5 | E3: 0.54166667 | F3: 월~금 | G3: 매주 토,일 | H3: 8 | I3: 5 | J3: 0 | K3: 0 | L3: 0 | M3: 0 | N3: =ROUNDUP(H3*6*365/12/7,0) -> 209 | O3: =I3*4.345*1.5 -> 32.5875 | P3: =K3*1.5 -> 0 | Q3: 0 | R3: =SUM(N3:Q3) -> 241.5875
F4: 월~금 | G4: 매주 토,일 | H4: 8 | I4: 0 | J4: 0 | K4: 0 | L4: 0 | M4: 0 | N4: =ROUNDUP(H4*6*365/12/7,0) -> 209 | O4: =I4*4.345*1.5 -> 0 | P4: =K4*1.5 -> 0 | Q4: =J4*5*365/12/7*0.5 -> 0 | R4: =SUM(N4:Q4) -> 209
A5: 현장 | B5: 0.29166667 | C5: 0.79166667 | D5: 12:00/ 15:00 | E5: 13:00/16:00 | F5: 월~금 | G5: 격주 토 매주 일 | H5: 8 | I5: 41.3 | J5: 0 | K5: 0 | L5: 0 | M5: 0 | N5: =ROUNDUP(H5*6*365/12/7,0) -> 209 | O5: =I5*1.5 -> 61.95 | P5: =K5*1.5 -> 0 | Q5: 0 | R5: =SUM(N5:Q5) -> 270.95 | S5: 격주 토 매주 일
A6: 본사(계약직) | B6: 0.375 | C6: 0.79166667 | D6: 0.5 | E6: 0.54166667 | F6: 월~금 | G6: 매주 토,일 | H6: 8 | I6: 0 | J6: 0 | K6: 0 | L6: 0 | M6: 0 | N6: =ROUNDUP(H6*6*365/12/7,0) -> 209 | O6: =I6*4.345*1.5 -> 0 | P6: =K6*1.5 -> 0 | Q6: 0 | R6: =SUM(N6:Q6) -> 209
A7: 현장(계약직) | B7: 0.375 | C7: 0.75 | D7: 0.5 | E7: 0.54166667 | F7: 월~금 | G7: 매주 토일 | H7: 8 | I7: 0 | J7: 0 | K7: 0 | L7: 0 | M7: 0 | N7: =ROUNDUP(H7*6*365/12/7,0) -> 209 | O7: =I7*4.345*1.5 -> 0 | P7: =K7*1.5 -> 0 | Q7: 0 | R7: =SUM(N7:Q7) -> 209
A12: 회사 정보
A14: 기 업 명 | D14: 제이엠건축인테리어 주식회사
A15: 사업자등록번호 | D15: 168-86-03200
A16: 소 재 지 | D16: 경상남도 창원시 의창구 평산로 135번길 4 , 2층
A17: 대 표 자 | D17: 이소연
AC21: 1

Sheet 포괄 급여계산
A1: 근로자 별 근로 정보 입력 | J1: 사용X | V1: 정보입력 | AB1: 정보입력 | AD1: 세전금액 | AE1: 사용X | AH1: 연도 | AI1: 최저시급 | AJ1: 최저임금
B2: 성명 | C2: 개인정보 | D2: 만 나이 | E2: 입사일 | F2: 퇴사일 | G2: 직책 | H2: 근무구분 | I2: 업무 | J2: 근로일 (ex. 월~금) | K2: 일 소정 근로시간 | L2: 통상시급 | M2: 기본시간 | N2: 근무시간 | P2: 휴게 시간 | R2: 포괄연장시간 | S2: 연장 추가시간 | U2: 기본급 | V2: 상여금 | X2: 식대 | Y2: 차량유지 | Z2: 연장근로 | AA2: 연장 추가시간 | AC2: 직책수당 | AD2: 월지급액(12등분) | AE2: 연봉총액 | AF2: 확인 | AG2: 최저임금 여부 확인 | AH2: 2025년 | AI2: 10030 | AJ2: 10320
A3: 1 | B3: 이소연 | C3: 8106200000000 | D3: =IFERROR(DATEDIF(DATE(IF(VALUE(MID(C3,8,1))<3,1900,2000)+VALUE(LEFT(C3,2)),VALUE(MID(C3,3,2)),VALUE(MID(C3,5,2))),TODAY(),"Y"),"") -> 44 | E3: 2024.11.01 | G3: 대표 | H3: 본사 | I3: - | J3: =IFERROR(VLOOKUP(H3,급여셋팅!$A$3:$R$7,6,0),"") -> 월~금 | K3: =VLOOKUP(H3,급여셋팅!$A$3:$R$7,8,0) -> 8 | L3: =IFERROR(AD3/M3,"") -> 32894.737 | M3: 209 | N3: =VLOOKUP(H3,급여셋팅!$A$3:$R$7,2,0) -> 0.375 | O3: =VLOOKUP(H3,급여셋팅!$A$3:$R$7,3,0) -> 0.75 | P3: =VLOOKUP(H3,급여셋팅!$A$3:$R$7,4,0) -> 0.5 | Q3: =VLOOKUP(H3,급여셋팅!$A$3:$R$7,5,0) -> 0.54166667 | R3: 0 | S3: =연장추가근로시!H3 -> 0 | U3: =IFERROR(AD3-X3-Y3-Z3-AC3,"") -> 6475000 | X3: 200000 | Y3: 200000 | Z3: =IFERROR(L3*R3,"") -> 0 | AA3: =IFERROR(L3*S3*1.5,"") -> 0 | AB3: =VLOOKUP(H3,급여셋팅!$A$3:$R$7,17,0) -> 0 | AD3: 6875000 | AE3: =IFERROR(ROUNDDOWN(AD3*12,-1),"") -> 82500000 | AF3: =IFERROR(SUM(U3:AC3)-AB3,"") -> 6875000 | AG3: =IFERROR(SUM(U3,X3,Y3),"") -> 6875000 | AH3: 2026년 | AI3: =AI2*209 -> 2096270 | AJ3: =AJ2*209 -> 2156880
A4: 2 | B4: 문준호 | C4: 7805200000000 | D4: =IFERROR(DATEDIF(DATE(IF(MID(C4,7,1)*1<3,1900,2000)+LEFT(C4,2), MID(C4,3,2), MID(C4,5,2) ), TODAY(), "Y" ), "") -> 47 | E4: 2023.09.04 | G4: 이사 | H4: 본사 | I4: - | J4: =IFERROR(VLOOKUP(H4,급여셋팅!$A$3:$R$7,6,0),"") -> 월~금 | K4: =VLOOKUP(H4,급여셋팅!$A$3:$R$7,8,0) -> 8 | L4: =IFERROR(AD4/M4,"") -> 32966.507 | M4: 209 | N4: =VLOOKUP(H4,급여셋팅!$A$3:$R$7,2,0) -> 0.375 | O4: =VLOOKUP(H4,급여셋팅!$A$3:$R$7,3,0) -> 0.75 | P4: =VLOOKUP(H4,급여셋팅!$A$3:$R$7,4,0) -> 0.5 | Q4: =VLOOKUP(H4,급여셋팅!$A$3:$R$7,5,0) -> 0.54166667 | R4: 0 | S4: =연장추가근로시!H4 -> 0 | U4: =IFERROR(AD4-X4-Y4-Z4-AC4,"") -> 6875000 | Z4: =IFERROR(L4*R4,"") -> 0 | AA4: =IFERROR(L4*S4,"") -> 0 | AB4: =VLOOKUP(H4,급여셋팅!$A$3:$R$7,17,0) -> 0 | AC4: 15000 | AD4: 6890000 | AE4: =IFERROR(ROUNDDOWN(AD4*12,-1),"") -> 82680000 | AF4: =IFERROR(SUM(U4:AC4)-AB4,"") -> 6890000 | AG4: =IFERROR(SUM(U4,X4,Y4),"") -> 6875000
A5: 3 | B5: 하동명 | C5: 9805180000000 | D5: =IFERROR(DATEDIF(DATE(IF(MID(C5,7,1)*1<3,1900,2000)+LEFT(C5,2), MID(C5,3,2), MID(C5,5,2) ), TODAY(), "Y" ), "") -> 27 | E5: 2025.08.04 | G5: 사원 | H5: 현장 | I5: 현장업무 | J5: 월~금 / 격주 토 | K5: =VLOOKUP(H5,급여셋팅!$A$3:$R$7,8,0) -> 8 | L5: =IFERROR(AD5/M5,"") -> 14516.848 | M5: =IFERROR(VLOOKUP(H5,급여셋팅!$A$3:$R$7,18,0),"") -> 270.95 | N5: =VLOOKUP(H5,급여셋팅!$A$3:$R$7,2,0) -> 0.29166667 | O5: =VLOOKUP(H5,급여셋팅!$A$3:$R$7,3,0) -> 0.79166667 | P5: =VLOOKUP(H5,급여셋팅!$A$3:$R$7,4,0) -> 12:00/ 15:00 | Q5: =VLOOKUP(H5,급여셋팅!$A$3:$R$7,5,0) -> 13:00/16:00 | R5: =IFERROR(VLOOKUP(H5,급여셋팅!$A$3:$R$7,15,0),"") -> 61.95 | S5: =연장추가근로시!H5 -> 0 | U5: =IFERROR(AD5-X5-Y5-Z5-AC5,"") -> 2834021.3 | X5: 200000 | Z5: =IFERROR(L5*R5,"") -> 899318.74 | AA5: =IFERROR(L5*S5,"") -> 0 | AB5: =VLOOKUP(H5,급여셋팅!$A$3:$R$7,17,0) -> 0 | AD5: 3933340 | AE5: =IFERROR(ROUNDDOWN(AD5*12,-1),"") -> 47200080 | AF5: =IFERROR(SUM(U5:AC5)-AB5,"") -> 3933340 | AG5: =IFERROR(SUM(U5,X5,Y5),"") -> 3034021.3
A6: 4 | B6: 정휘범 | C6: 000420-3861929 | D6: =IFERROR(DATEDIF(DATE(IF(VALUE(MID(C6,8,1))<3,1900,2000)+VALUE(LEFT(C6,2)),VALUE(MID(C6,3,2)),VALUE(MID(C6,5,2))),TODAY(),"Y"),"") -> 25 | E6: 2025.03.24 | G6: 사원 | H6: 본사 | I6: 디자인 | J6: =IFERROR(VLOOKUP(H6,급여셋팅!$A$3:$R$7,6,0),"") -> 월~금 | K6: =VLOOKUP(H6,급여셋팅!$A$3:$R$7,8,0) -> 8 | L6: =IFERROR(AD6/M6,"") -> 10320 | M6: =IFERROR(VLOOKUP(H6,급여셋팅!$A$3:$R$7,18,0),"") -> 241.5875 | N6: =VLOOKUP(H6,급여셋팅!$A$3:$R$7,2,0) -> 0.375 | O6: =VLOOKUP(H6,급여셋팅!$A$3:$R$7,3,0) -> 0.75 | P6: =VLOOKUP(H6,급여셋팅!$A$3:$R$7,4,0) -> 0.5 | Q6: =VLOOKUP(H6,급여셋팅!$A$3:$R$7,5,0) -> 0.54166667 | R6: =IFERROR(VLOOKUP(H6,급여셋팅!$A$3:$R$7,15,0),"") -> 32.5875 | S6: =연장추가근로시!H6 -> 0 | U6: =IFERROR(AD6-X6-Y6-Z6-AC6,"") -> 1956880 | X6: 200000 | Z6: =IFERROR(L6*R6,"") -> 336303 | AA6: =IFERROR(L6*S6,"") -> 0 | AB6: =VLOOKUP(H6,급여셋팅!$A$3:$R$7,17,0) -> 0 | AD6: 2493183 | AE6: =IFERROR(ROUNDDOWN(AD6*12,-1),"") -> 29918190 | AF6: =IFERROR(SUM(U6:AC6)-AB6,"") -> 2493183 | AG6: =IFERROR(SUM(U6,X6,Y6),"") -> 2156880
A7: 5 | D7: =IFERROR(DATEDIF(DATE(IF(MID(C7,7,1)*1<3,1900,2000)+LEFT(C7,2),MID(C7,3,2),MID(C7,5,2)),TODAY(),"Y"),"") | K7: =VLOOKUP(H7,급여셋팅!$A$3:$R$7,8,0) -> #N/A | L7: =IFERROR(AD7/M7,"") | M7: =IFERROR(VLOOKUP(H7,급여셋팅!$A$3:$R$7,18,0),"") | N7: =VLOOKUP(H7,급여셋팅!$A$3:$R$7,2,0) -> #N/A | O7: =VLOOKUP(H7,급여셋팅!$A$3:$R$7,3,0) -> #N/A | P7: =VLOOKUP(H7,급여셋팅!$A$3:$R$7,4,0) -> #N/A | Q7: =VLOOKUP(H7,급여셋팅!$A$3:$R$7,5,0) -> #N/A | R7: =IFERROR(VLOOKUP(H7,급여셋팅!$A$3:$R$7,15,0),"") | S7: =연장추가근로시!H7 -> 0 | U7: =IFERROR(AD7-X7-Y7-Z7-AC7,"") | Z7: =IFERROR(L7*R7,"") | AA7: =IFERROR(L7*S7,"") | AB7: =VLOOKUP(H7,급여셋팅!$A$3:$R$7,17,0) -> #N/A | AE7: =IFERROR(ROUNDDOWN(AD7*12,-1),"") -> 0 | AF7: =IFERROR(SUM(U7:AC7)-AB7,"") | AG7: =IFERROR(SUM(U7,X7,Y7),"") -> 0
A8: 6 | D8: =IFERROR(DATEDIF(DATE(IF(MID(C8,7,1)*1<3,1900,2000)+LEFT(C8,2), MID(C8,3,2), MID(C8,5,2) ), TODAY(), "Y" ), "") | K8: =VLOOKUP(H8,급여셋팅!$A$3:$R$7,8,0) -> #N/A | L8: =IFERROR(AD8/M8,"") | M8: =IFERROR(VLOOKUP(H8,급여셋팅!$A$3:$R$7,18,0),"") | N8: =VLOOKUP(H8,급여셋팅!$A$3:$R$7,2,0) -> #N/A | O8: =VLOOKUP(H8,급여셋팅!$A$3:$R$7,3,0) -> #N/A | P8: =VLOOKUP(H8,급여셋팅!$A$3:$R$7,4,0) -> #N/A | Q8: =VLOOKUP(H8,급여셋팅!$A$3:$R$7,5,0) -> #N/A | R8: =IFERROR(VLOOKUP(H8,급여셋팅!$A$3:$R$7,15,0),"") | S8: =연장추가근로시!H8 -> 0 | U8: =IFERROR(AD8-X8-Y8-Z8-AC8,"") | Z8: =IFERROR(L8*R8,"") | AA8: =IFERROR(L8*S8,"") | AB8: =VLOOKUP(H8,급여셋팅!$A$3:$R$7,17,0) -> #N/A | AE8: =IFERROR(ROUNDDOWN(AD8*12,-1),"") -> 0 | AF8: =IFERROR(SUM(U8:AC8)-AB8,"") | AG8: =IFERROR(SUM(U8,X8,Y8),"") -> 0
A9: 7 | D9: =IFERROR( DATEDIF( DATE( IF(MID(C9,7,1)*1<3,1900,2000)+LEFT(C9,2), MID(C9,3,2), MID(C9,5,2) ), TODAY(), "Y" ), "") | K9: =VLOOKUP(H9,급여셋팅!$A$3:$R$7,8,0) -> #N/A | L9: =IFERROR(AD9/M9,"") | M9: =IFERROR(VLOOKUP(H9,급여셋팅!$A$3:$R$7,18,0),"") | N9: =VLOOKUP(H9,급여셋팅!$A$3:$R$7,2,0) -> #N/A | O9: =VLOOKUP(H9,급여셋팅!$A$3:$R$7,3,0) -> #N/A | P9: =VLOOKUP(H9,급여셋팅!$A$3:$R$7,4,0) -> #N/A | Q9: =VLOOKUP(H9,급여셋팅!$A$3:$R$7,5,0) -> #N/A | R9: =IFERROR(VLOOKUP(H9,급여셋팅!$A$3:$R$7,15,0),"") | S9: =연장추가근로시!J9 -> 0 | U9: =IFERROR(AD9-X9-Y9-Z9-AC9,"") | Z9: =IFERROR(L9*R9,"") | AA9: =IFERROR(L9*S9,"") | AB9: =VLOOKUP(H9,급여셋팅!$A$3:$R$7,17,0) -> #N/A | AE9: =IFERROR(ROUNDDOWN(AD9*12,-1),"") -> 0 | AF9: =IFERROR(SUM(U9:AC9)-AB9,"") | AG9: =IFERROR(SUM(U9,X9,Y9),"") -> 0
A10: 8 | D10: =IFERROR( DATEDIF( DATE( IF(MID(C10,7,1)*1<3,1900,2000)+LEFT(C10,2), MID(C10,3,2), MID(C10,5,2) ), TODAY(), "Y" ), "") | K10: =VLOOKUP(H10,급여셋팅!$A$3:$R$7,8,0) -> #N/A | L10: =IFERROR(AD10/M10,"") | M10: =IFERROR(VLOOKUP(H10,급여셋팅!$A$3:$R$7,18,0),"") | N10: =VLOOKUP(H10,급여셋팅!$A$3:$R$7,2,0) -> #N/A | O10: =VLOOKUP(H10,급여셋팅!$A$3:$R$7,3,0) -> #N/A | P10: =VLOOKUP(H10,급여셋팅!$A$3:$R$7,4,0) -> #N/A | Q10: =VLOOKUP(H10,급여셋팅!$A$3:$R$7,5,0) -> #N/A | R10: =IFERROR(VLOOKUP(H10,급여셋팅!$A$3:$R$7,15,0),"") | S10: =연장추가근로시!J10 -> 0 | U10: =IFERROR(AD10-X10-Y10-Z10-AC10,"") | Z10: =IFERROR(L10*R10,"") | AA10: =IFERROR(L10*S10,"") | AB10: =VLOOKUP(H10,급여셋팅!$A$3:$R$7,17,0) -> #N/A | AE10: =IFERROR(ROUNDDOWN(AD10*12,-1),"") -> 0 | AF10: =IFERROR(SUM(U10:AC10)-AB10,"") | AG10: =IFERROR(SUM(U10,X10,Y10),"") -> 0
A11: 9 | D11: =IFERROR( DATEDIF( DATE( IF(MID(C11,7,1)*1<3,1900,2000)+LEFT(C11,2), MID(C11,3,2), MID(C11,5,2) ), TODAY(), "Y" ), "") | K11: =VLOOKUP(H11,급여셋팅!$A$3:$R$7,8,0) -> #N/A | L11: =IFERROR(AD11/M11,"") | M11: =IFERROR(VLOOKUP(H11,급여셋팅!$A$3:$R$7,18,0),"") | N11: =VLOOKUP(H11,급여셋팅!$A$3:$R$7,2,0) -> #N/A | O11: =VLOOKUP(H11,급여셋팅!$A$3:$R$7,3,0) -> #N/A | P11: =VLOOKUP(H11,급여셋팅!$A$3:$R$7,4,0) -> #N/A | Q11: =VLOOKUP(H11,급여셋팅!$A$3:$R$7,5,0) -> #N/A | R11: =IFERROR(VLOOKUP(H11,급여셋팅!$A$3:$R$7,15,0),"") | S11: =연장추가근로시!J11 -> 0 | U11: =IFERROR(AD11-X11-Y11-Z11-AC11,"") | Z11: =IFERROR(L11*R11,"") | AA11: =IFERROR(L11*S11,"") | AB11: =VLOOKUP(H11,급여셋팅!$A$3:$R$7,17,0) -> #N/A | AE11: =IFERROR(ROUNDDOWN(AD11*12,-1),"") -> 0 | AF11: =IFERROR(SUM(U11:AC11)-AB11,"") | AG11: =IFERROR(SUM(U11,X11,Y11),"") -> 0
A12: 10 | D12: =IFERROR( DATEDIF( DATE( IF(MID(C12,7,1)*1<3,1900,2000)+LEFT(C12,2), MID(C12,3,2), MID(C12,5,2) ), TODAY(), "Y" ), "") | K12: =VLOOKUP(H12,급여셋팅!$A$3:$R$7,8,0) -> #N/A | L12: =IFERROR(AD12/M12,"") | M12: =IFERROR(VLOOKUP(H12,급여셋팅!$A$3:$R$7,18,0),"") | N12: =VLOOKUP(H12,급여셋팅!$A$3:$R$7,2,0) -> #N/A | O12: =VLOOKUP(H12,급여셋팅!$A$3:$R$7,3,0) -> #N/A | P12: =VLOOKUP(H12,급여셋팅!$A$3:$R$7,4,0) -> #N/A | Q12: =VLOOKUP(H12,급여셋팅!$A$3:$R$7,5,0) -> #N/A | R12: =IFERROR(VLOOKUP(H12,급여셋팅!$A$3:$R$7,15,0),"") | S12: =연장추가근로시!J12 -> 0 | U12: =IFERROR(AD12-X12-Y12-Z12-AC12,"") | Z12: =IFERROR(L12*R12,"") | AA12: =IFERROR(L12*S12,"") | AB12: =VLOOKUP(H12,급여셋팅!$A$3:$R$7,17,0) -> #N/A | AE12: =IFERROR(ROUNDDOWN(AD12*12,-1),"") -> 0 | AF12: =IFERROR(SUM(U12:AC12)-AB12,"") | AG12: =IFERROR(SUM(U12,X12,Y12),"") -> 0
U14: =U6/31*8 -> 505001.29 | X14: =X6/31*8 -> 51612.903 | Z14: =Z6/31*8 -> 86787.871

Sheet 연장추가근로시
A1: 1. 추가 근로시 입력
A2: 성명 | B2: 직책 | C2: 근무구분 | D2: 평일 근로시간 | E2: 연장 근로시간 | F2: 연장근로시간 | G2: 추가 연장 근로시간 | H2: 연장근로시간 | I2: 통상시급 | J2: 추가 연장수당
A3: 이소연 | B3: 대표 | C3: 본사 | D3: 8 | E3: 5 | F3: =E3*4.345*1.5 -> 32.5875 | H3: =G3*1.5 -> 0 | I3: 32894.737 | J3: =H3*I3 -> 0
A4: 문준호 | B4: 이사 | C4: 본사 | D4: 8 | E4: 5 | F4: =E4*4.345*1.5 -> 32.5875 | H4: =G4*1.5 -> 0 | I4: 32966.507 | J4: =H4*I4 -> 0
A5: 하동명 | B5: 사원 | C5: 현장 | D5: 8 | E5: 41.3 | F5: =E5*1.5 -> 61.95 | H5: =G5*1.5 -> 0 | I5: 14517 | J5: =H5*I5 -> 0
H6: =G6*1.5 -> 0 | J6: =H6*I6 -> 0
H7: =G7*1.5 -> 0 | J7: =H7*I7 -> 0
A12: 2. 조퇴 계산
A14: 성명 | B14: 직책 | C14: 근무구분 | D14: 통상시급 | E14: 일 통상임금 | F14: 조퇴 근로시간 | G14: 조퇴 시 급여 | H14: 공제액
A15: 이소연 | B15: 대표 | C15: 본사 | D15: 32894.737 | E15: =D15*8 -> 263157.89 | F15: 5 | G15: =D15*F15 -> 164473.68 | H15: =E15-G15 -> 98684.211
A16: 문준호 | B16: 이사 | C16: 본사 | D16: 32966.507 | E16: =D16*8 -> 263732.06 | G16: =D16*F16 -> 0 | H16: =E16-G16 -> 263732.06
A17: 하동명 | B17: 사원 | C17: 현장 | D17: 14516.848 | E17: =D17*8 -> 116134.79 | G17: =D17*F17 -> 0 | H17: =E17-G17 -> 116134.79
E18: =D18*8 -> 0 | G18: =D18*F18 -> 0 | H18: =E18-G18 -> 0
E19: =D19*8 -> 0 | G19: =D19*F19 -> 0 | H19: =E19-G19 -> 0
G20: =D20*F20 -> 0 | H20: =E20-G20 -> 0

Sheet 급여대장
A1: =TODAY() -> 46118 | AG1: 고용보험 | AH1: 고용보험 | AI1: 0.9
AG2: 건강보험 | AH2: 건강보험 | AI2: 3.595
A3: 회사명 | AB3: 근속 월 | AD3: 46082 | AH3: 장기요양 | AI3: 0.1314
A4: 제이엠건축인테리어 주식회사 | AB4: 지급일 | AD4: 매월 5일 | AG4: 연금보험 | AH4: 연금보험 | AI4: 4.75
A5: 연번 | B5: 성명 | C5: 생년월일 | D5: 피부양자 | E5: 입사일 | F5: 만나이 | G5: 기 본 급 | H5: 식대 | I5: 차량 유지비 | J5: 연장근로 | K5: 연장 추가수당 | L5: 직책수당 | M5: 상여금 | N5: 급여 합계 | O5: 과세 합계 | P5: 건강보험 | Q5: 장기요양 | R5: 국민연금 | S5: 고용보험 | T5: 소득세 | U5: 주민세 | W5: 프로그램 공제 | X5: 조퇴공제 | Y5: 건강정산 | Z5: 장기요양정산 | AA5: 지급총액 | AB5: 공제합계 | AC5: 두리누리 | AD5: 차감지급액 | AE5: 연차 개수 (2025) | AF5: 미사용 연차 (2025) | AH5: 연금상한 | AI5: 6370000 | AJ5: 연금상한공제액 | AK5: =AI5*AI4% -> 302575
A6: =ROW(A6)-5 -> 1 | B6: ='포괄 급여계산'!B3 -> 이소연 | C6: ='포괄 급여계산'!C3 -> 8106200000000 | D6: 2 | E6: ='포괄 급여계산'!E3 -> 2024.11.01 | F6: ='포괄 급여계산'!D3 -> 44 | G6: ='포괄 급여계산'!U3 -> 6475000 | H6: ='포괄 급여계산'!X3 -> 200000 | I6: ='포괄 급여계산'!Y3 -> 200000 | J6: ='포괄 급여계산'!Z3 -> 0 | K6: ='포괄 급여계산'!AA3 -> 0 | L6: ='포괄 급여계산'!AC3 -> 0 | M6: ='포괄 급여계산'!V3 -> 0 | N6: =SUM(G6:M6) -> 6875000 | O6: =SUM(G6,J6,K6,L6+M6) -> 6475000 | P6: 247150 | Q6: 32470 | R6: 302570 | S6: 0 | T6: {=IFERROR(INDEX(간이세액표!$D:$O,MATCH(O6/1000, 간이세액표!$A:$A, 1), D6), 0)} -> 562470 | U6: =ROUNDDOWN(T6*10%,-1) -> 56240 | AA6: =SUM(G6:M6) -> 6875000 | AB6: =SUM(P6:Z6) -> 1200900 | AD6: =AA6-AB6 -> 5674100 | AE6: - | AF6: - | AH6: 연금하한 | AI6: 400000 | AJ6: 연금하한공제액 | AK6: =AI6*AI4% -> 19000
A7: =ROW(A7)-5 -> 2 | B7: ='포괄 급여계산'!B4 -> 문준호 | C7: ='포괄 급여계산'!C4 -> 7805200000000 | D7: 2 | E7: ='포괄 급여계산'!E4 -> 2023.09.04 | F7: ='포괄 급여계산'!D4 -> 47 | G7: ='포괄 급여계산'!U4 -> 6875000 | H7: ='포괄 급여계산'!X4 -> 0 | I7: ='포괄 급여계산'!Y4 -> 0 | J7: ='포괄 급여계산'!Z4 -> 0 | K7: ='포괄 급여계산'!AA4 -> 0 | L7: ='포괄 급여계산'!AC4 -> 15000 | M7: ='포괄 급여계산'!V4 -> 0 | N7: =SUM(G7:M7) -> 6890000 | O7: =SUM(G7,J7,K7,L7+M7) -> 6890000 | P7: 247690 | Q7: 32540 | R7: 302570 | S7: 0 | T7: {=IFERROR(INDEX(간이세액표!$D:$O,MATCH(O7/1000, 간이세액표!$A:$A, 1), D7), 0)} -> 657220 | U7: =ROUNDDOWN(T7*10%,-1) -> 65720 | AA7: =SUM(G7:M7) -> 6890000 | AB7: =SUM(P7:Z7) -> 1305740 | AD7: =AA7-AB7 -> 5584260 | AE7: - | AF7: -
A8: =ROW(A8)-5 -> 3 | B8: ='포괄 급여계산'!B5 -> 하동명 | C8: ='포괄 급여계산'!C5 -> 9805180000000 | D8: 1 | E8: ='포괄 급여계산'!E5 -> 2025.08.04 | F8: ='포괄 급여계산'!D5 -> 27 | G8: ='포괄 급여계산'!U5 -> 2834021.3 | H8: ='포괄 급여계산'!X5 -> 200000 | I8: ='포괄 급여계산'!Y5 -> 0 | J8: ='포괄 급여계산'!Z5 -> 899318.74 | K8: ='포괄 급여계산'!AA5 -> 0 | L8: ='포괄 급여계산'!AC5 -> 0 | M8: ='포괄 급여계산'!V5 -> 0 | N8: =SUM(G8:M8) -> 3933340 | O8: =SUM(G8,J8,K8,L8+M8) -> 3733340 | P8: 122230 | Q8: 16060 | R8: 161500 | S8: =IF(F8 >= 65, 0, ROUNDDOWN(O8 * 0.9%, -1)) -> 33600 | T8: {=IFERROR(INDEX(간이세액표!$D:$O,MATCH(O8/1000, 간이세액표!$A:$A, 1), D8), 0)} -> 154110 | U8: =ROUNDDOWN(T8*10%,-1) -> 15410 | AA8: =SUM(G8:M8) -> 3933340 | AB8: =SUM(P8:Z8) -> 502910 | AD8: =AA8-AB8 -> 3430430 | AE8: - | AF8: -
A9: =ROW(A9)-5 -> 4 | B9: ='포괄 급여계산'!B6 -> 정휘범 | C9: ='포괄 급여계산'!C6 -> 000420-3861929 | D9: 1 | E9: ='포괄 급여계산'!E6 -> 2025.03.24 | F9: ='포괄 급여계산'!D6 -> 25 | G9: 505001 | H9: 51613 | I9: ='포괄 급여계산'!Y6 -> 0 | J9: 86788 | K9: ='포괄 급여계산'!AA6 -> 0 | L9: ='포괄 급여계산'!AC6 -> 0 | M9: ='포괄 급여계산'!V6 -> 0 | N9: =SUM(G9:M9) -> 643402 | O9: =SUM(G9,J9,K9,L9+M9) -> 591789 | S9: 0 | T9: {=IFERROR(INDEX(간이세액표!$D:$O,MATCH(O9/1000, 간이세액표!$A:$A, 1), D9), 0)} -> 0 | U9: =ROUNDDOWN(T9*10%,-1) -> 0 | AA9: =SUM(G9:M9) -> 643402 | AB9: =SUM(P9:Z9) -> 0 | AD9: =AA9-AB9 -> 643402 | AE9: - | AF9: -
A10: =ROW(A10)-5 -> 5 | B10: ='포괄 급여계산'!B7 -> 0 | C10: ='포괄 급여계산'!C7 -> 0 | D10: 1 | E10: ='포괄 급여계산'!E7 -> 0 | F10: ='포괄 급여계산'!D7 | G10: ='포괄 급여계산'!U7 | H10: ='포괄 급여계산'!X7 -> 0 | I10: ='포괄 급여계산'!Y7 -> 0 | J10: ='포괄 급여계산'!Z7 | K10: ='포괄 급여계산'!AA7 | L10: ='포괄 급여계산'!AC7 -> 0 | M10: ='포괄 급여계산'!V7 -> 0 | N10: =SUM(G10:M10) -> 0 | O10: =SUM(G10,J10,K10,L10+M10) -> 0 | S10: =IF(F10 >= 65, 0, ROUNDDOWN(O10 * 0.9%, -1)) -> 0 | T10: {=IFERROR(INDEX(간이세액표!$D:$O,MATCH(O10/1000, 간이세액표!$A:$A, 1), D10), 0)} -> 0 | U10: =ROUNDDOWN(T10*10%,-1) -> 0 | AA10: =SUM(G10:M10) -> 0 | AB10: =SUM(P10:Z10) -> 0 | AD10: =AA10-AB10 -> 0 | AE10: - | AF10: -
A11: 6 | B11: ='포괄 급여계산'!B8 -> 0 | C11: ='포괄 급여계산'!C8 -> 0 | D11: 1 | E11: ='포괄 급여계산'!E8 -> 0 | F11: ='포괄 급여계산'!D8 | K11: ='포괄 급여계산'!AA8 | L11: ='포괄 급여계산'!AC8 -> 0 | M11: ='포괄 급여계산'!V8 -> 0 | N11: =SUM(G11:M11) -> 0 | O11: =SUM(G11,J11,K11,L11+M11) -> 0 | S11: =IF(F11 >= 65, 0, ROUNDDOWN(O11 * 0.9%, -1)) -> 0 | T11: {=IFERROR(INDEX(간이세액표!$D:$O,MATCH(O11/1000, 간이세액표!$A:$A, 1), D11), 0)} -> 0 | U11: =ROUNDDOWN(T11*10%,-1) -> 0 | AA11: =SUM(G11:M11) -> 0 | AB11: =SUM(P11:Z11) -> 0 | AD11: =AA11-AB11 -> 0 | AE11: - | AF11: -
A12: =ROW(A12)-5 -> 7 | B12: ='포괄 급여계산'!B9 -> 0 | C12: ='포괄 급여계산'!C9 -> 0 | D12: 1 | E12: ='포괄 급여계산'!E9 -> 0 | F12: ='포괄 급여계산'!D9 | G12: ='포괄 급여계산'!U9 | H12: ='포괄 급여계산'!X9 -> 0 | I12: ='포괄 급여계산'!Y9 -> 0 | J12: ='포괄 급여계산'!Z9 | K12: ='포괄 급여계산'!AA9 | L12: ='포괄 급여계산'!AC9 -> 0 | M12: ='포괄 급여계산'!V9 -> 0 | N12: =SUM(G12:M12) -> 0 | O12: =SUM(G12,J12,K12,L12+M12) -> 0 | P12: =ROUNDDOWN(O12*7.19%/2,-1) -> 0 | Q12: =ROUNDDOWN(P12*13.14%,-1) -> 0 | R12: =IF(F12 >= 60, 0, ROUNDDOWN(MIN(O12, 6370000) * 4.75%, -1)) -> 0 | S12: =IF(F12 >= 65, 0, ROUNDDOWN(O12 * 0.9%, -1)) -> 0 | T12: {=IFERROR(INDEX(간이세액표!$D:$O,MATCH(O12/1000, 간이세액표!$A:$A, 1), D12), 0)} -> 0 | U12: =ROUNDDOWN(T12*10%,-1) -> 0 | W12: 0 | AA12: =SUM(G12:M12) -> 0 | AB12: =SUM(P12:Z12) -> 0 | AD12: =AA12-AB12 -> 0 | AE12: - | AF12: -
A13: =ROW(A13)-5 -> 8 | B13: ='포괄 급여계산'!B10 -> 0 | C13: ='포괄 급여계산'!C10 -> 0 | D13: 1 | E13: ='포괄 급여계산'!E10 -> 0 | F13: ='포괄 급여계산'!D10 | G13: ='포괄 급여계산'!U10 | H13: ='포괄 급여계산'!X10 -> 0 | I13: ='포괄 급여계산'!Y10 -> 0 | J13: ='포괄 급여계산'!Z10 | K13: ='포괄 급여계산'!AA10 | L13: ='포괄 급여계산'!AC10 -> 0 | M13: ='포괄 급여계산'!V10 -> 0 | N13: =SUM(G13:M13) -> 0 | O13: =SUM(G13,J13,K13,L13+M13) -> 0 | P13: =ROUNDDOWN(O13*7.19%/2,-1) -> 0 | Q13: =ROUNDDOWN(P13*13.14%,-1) -> 0 | R13: =IF(F13 >= 60, 0, ROUNDDOWN(MIN(O13, 6370000) * 4.5%, -1)) -> 0 | S13: =IF(F13 >= 65, 0, ROUNDDOWN(O13 * 0.9%, -1)) -> 0 | T13: {=IFERROR(INDEX(간이세액표!$D:$O,MATCH(O13/1000, 간이세액표!$A:$A, 1), D13), 0)} -> 0 | U13: =ROUNDDOWN(T13*10%,-1) -> 0 | W13: 0 | AA13: =SUM(G13:M13) -> 0 | AB13: =SUM(P13:Z13) -> 0 | AD13: =AA13-AB13 -> 0 | AE13: - | AF13: -
A14: =ROW(A14)-5 -> 9 | B14: ='포괄 급여계산'!B11 -> 0 | C14: ='포괄 급여계산'!C11 -> 0 | D14: 1 | E14: ='포괄 급여계산'!E11 -> 0 | F14: ='포괄 급여계산'!D11 | G14: ='포괄 급여계산'!U11 | H14: ='포괄 급여계산'!X11 -> 0 | I14: ='포괄 급여계산'!Y11 -> 0 | J14: ='포괄 급여계산'!Z11 | K14: ='포괄 급여계산'!AA11 | L14: ='포괄 급여계산'!AC11 -> 0 | M14: ='포괄 급여계산'!V11 -> 0 | N14: =SUM(G14:M14) -> 0 | O14: =SUM(G14,J14,K14,L14+M14) -> 0 | P14: =ROUNDDOWN(O14*7.09%/2,-1) -> 0 | Q14: =ROUNDDOWN(P14*12.95%,-1) -> 0 | R14: =IF(F14 >= 60, 0, ROUNDDOWN(MIN(O14, 6370000) * 4.5%, -1)) -> 0 | S14: =IF(F14 >= 65, 0, ROUNDDOWN(O14 * 0.9%, -1)) -> 0 | T14: {=IFERROR(INDEX(간이세액표!$D:$O,MATCH(O14/1000, 간이세액표!$A:$A, 1), D14), 0)} -> 0 | U14: =ROUNDDOWN(T14*10%,-1) -> 0 | W14: 0 | AA14: =SUM(G14:M14) -> 0 | AB14: =SUM(P14:Z14) -> 0 | AD14: =AA14-AB14 -> 0 | AE14: - | AF14: -
A15: =ROW(A15)-5 -> 10 | B15: ='포괄 급여계산'!B12 -> 0 | C15: ='포괄 급여계산'!C12 -> 0 | D15: 1 | E15: ='포괄 급여계산'!E12 -> 0 | F15: ='포괄 급여계산'!D12 | G15: ='포괄 급여계산'!U12 | H15: ='포괄 급여계산'!X12 -> 0 | I15: ='포괄 급여계산'!Y12 -> 0 | J15: ='포괄 급여계산'!Z12 | K15: ='포괄 급여계산'!AA12 | L15: ='포괄 급여계산'!AC12 -> 0 | M15: ='포괄 급여계산'!V12 -> 0 | N15: =SUM(G15:M15) -> 0 | O15: =SUM(G15,J15,K15,L15+M15) -> 0 | P15: =ROUNDDOWN(O15*7.09%/2,-1) -> 0 | Q15: =ROUNDDOWN(P15*12.95%,-1) -> 0 | R15: =IF(F15 >= 60, 0, ROUNDDOWN(MIN(O15, 6370000) * 4.5%, -1)) -> 0 | S15: =IF(F15 >= 65, 0, ROUNDDOWN(O15 * 0.9%, -1)) -> 0 | T15: {=IFERROR(INDEX(간이세액표!$D:$O,MATCH(O15/1000, 간이세액표!$A:$A, 1), D15), 0)} -> 0 | U15: =ROUNDDOWN(T15*10%,-1) -> 0 | W15: 0 | AA15: =SUM(G15:M15) -> 0 | AB15: =SUM(P15:Z15) -> 0 | AD15: =AA15-AB15 -> 0 | AE15: - | AF15: -
A16: 총 합계 | G16: =SUM(G6:G15) -> 16689022 | H16: =SUM(H6:H15) -> 451613 | I16: =SUM(I6:I15) -> 200000 | J16: =SUM(J6:J15) -> 986106.74 | K16: =SUM(K6:K15) -> 0 | L16: =SUM(L6:L15) -> 15000 | M16: =SUM(M6:M15) -> 0 | N16: =SUM(N6:N15) -> 18341742 | O16: =SUM(O6:O15) -> 17690129 | P16: =IFERROR(SUM(P6:P15),0) -> 617070 | Q16: =IFERROR(SUM(Q6:Q15),0) -> 81070 | R16: =IFERROR(SUM(R6:R15),0) -> 766640 | S16: =IFERROR(SUM(S6:S15),0) -> 33600 | T16: =IFERROR(SUM(T6:T15),0) -> 1373800 | U16: =IFERROR(SUM(U6:U15),0) -> 137370 | V16: =SUM(V6:V10) -> 0 | W16: =IFERROR(SUM(W6:W15),0) -> 0 | X16: =IFERROR(SUM(X6:X15),0) -> 0 | Y16: =SUM(Y6:Y10) -> 0 | AA16: =IFERROR(SUM(AA6:AA15),0) -> 18341742 | AB16: =IFERROR(SUM(AB6:AB15),0) -> 3009550 | AC16: =SUM(AC6:AC15) -> 0 | AD16: =IFERROR(SUM(AD6:AD15),0) -> 15332192
X22: 5월 급여 반영 | Y22: 건강보험 정산
X23: 문준호 | Y23: 114180 | Z23: 14760
X24: 하동명 | Y24: 68640 | Z24: 8920

Sheet 근로계약서(계약직)
A1: 근 로 계 약 서 | M1: 1
A3: =급여셋팅!$D$14 -> 제이엠건축인테리어 주식회사 | C3: (이하 "갑"이라고 한다)와 | E3: =VLOOKUP($M$1,'포괄 급여계산'!$A$3:$AG$12,2,0) -> 이소연 | F3: (이하 "을"이라고 한다)은/는 근로계약을 체결하고 상호 성실히 이행한다.
A4: 근로계약기간 수습기간 | B4: ① 근로계약기간은 | C4: =VLOOKUP($M$1,'포괄 급여계산'!$A$3:$AG$12,5,0) -> 2024.11.01 | D4: 부터 0000년 00월 00일 까지로 한다.
B5: ② 입사일로부터 | D5: 까지 수습기간으로 하며 해당 기간 중 임금은 법률이 정하는 바에 의하여
B6: 조절하여 지급할 수 있다.
B7: ③ 수습기간 만료 후 채용여부를 결정하되 수습기간 중 본인근무실태, 성실성, 근면성 등을 평가하여 부적격하다고 판단될 때에는
B8: 수습기간 중이라도 본 계약을 취소할 수 있다.
A9: 근무장소 담당 업무 | B9: ① 근로장소: | C9: =VLOOKUP($M$1,'포괄 급여계산'!$A$3:$AG$12,8,0) -> 본사 | E9: 또는 "갑"이 지정한 장소.
B10: ② 담당업무: | C10: =VLOOKUP($M$1,'포괄 급여계산'!$A$3:$AG$12,9,0) -> - | E10: 및 그와 관련된 업무로 한다.
B11: ③ "갑"은 필요한 경우 전 2항에서 정한 근로장소 및 업무의 내용을 변경할 수 있으며 "을"은 정당한 이유가 없는 한 이에 응해야한다.
A12: 근로시간 휴게시간 | B12: ① 소정근로시간 : | C12: =VLOOKUP($M$1,'포괄 급여계산'!$A$3:$AC$12,14,0) -> 0.375 | D12: 부터 | E12: =VLOOKUP($M$1,'포괄 급여계산'!$A$3:$AC$12,15,0) -> 0.75 | F12: 까지
B13: ② 휴게시간 : | C13: 시작 | D13: =VLOOKUP($M$1,'포괄 급여계산'!$A$3:$AC$12,16,0) -> 0.5 | E13: 종료 | F13: =VLOOKUP($M$1,'포괄 급여계산'!$A$3:$AC$12,17,0) -> 0.54166667
B14: ③ 전 2항의 근로시간 및 휴게시간은 "갑"의 사정에 따라 필요한 경우 이를 변경하여 운영할 수 있다.
A15: 근로일 및 휴일 | B15: ① 소정근로일은 | C15: =VLOOKUP($M$1,'포괄 급여계산'!$A$3:$AC$12,9,0) -> - | D15: 이며 토요일은 무급휴무일로 한다.
B16: ② 다음 각 호의 1에 정하는 날은 유급휴일로 한다. 다만, "을"이 1주 동안에 소정근로일을 개근하지 아니한 경우 주휴일은 무급으로 하며
B17: 각 호의 휴일이 중복되는 경우에는 하나의 휴일로 취급한다.
B18: 1. 주휴일(일요일) 2. 근로자의 날(매년 5월 1일) 3. 기타 회사에서 정한 날
B19: ③ 전 2항의 근로일과 주휴일은 "갑"의 사정에 따라 필요한 경우 이를 변경할 수 있으며 각 사업장의 상황에 따라 일요일이 아닌 근로일에
B20: 쉬는 경우에는 주휴일을 사용한 것으로 갈음한다. 또한 업무상 필요한 경우 휴일을 해당 직원에게 24시간 전에 미리 통보하여 다른 날로
B21: 부여할 수 있다. 이 경우 “갑”은 휴일근로수당의 지급의무를 면한다.
A22: 연장·휴일 및 야간근로 | B22: ① “갑”은 “을”의 동의를 받아 시간외(연장,야간,휴일)근로를 명할 수 있다.
B23: ② 시간외(연장,야간,휴일)근로는 원칙적으로 상사의 명령 또는 상사의 사전승인을 득한 경우에만 인정된다.
B24: ③ "갑"은 근로자대표와의 서면합의에 따라 연장•야간•휴일근로에 대하여 임금을 지급하는 것을 갈음하여 휴가를 줄 수 있다.
A25: 임금 | B25: “을”의 급여내역은 연봉계약서에 의한다.
A26: 연차휴가 | B26: ① 1년간 80퍼센트 이상 출근한 직원에게는 15일의 유급휴가를 주며 계속근로연수가 1년 미만인 직원 또는 1년간 80퍼센트 미만
B27: 출근한 직원에 대하여는 1월간 개근 시 1일의 유급휴가를 준다.
B28: ② 기타 연차 유급휴가에 관한 사항은 취업규칙 및 근로기준법에서 정하는 바에 따른다.
B29: ③ 착공 및 조기준공 등등을 포함하여 공사현장에 따라 불가피하게 휴무가 발생 한 경우 연차사용으로 대체 할 수 있다.
A30: 비밀준수의무 | B30: ①"을"이 근무 중 고의 또는 과실로 "갑"에게 손해를 끼치거나 본인이나 타인의 임금내역을 고의∙과실로 공개 또는 누설하는 경우에는
B31: 징계와 더불어 손해배상 등 민∙형사상의 책임을 물을 수 있다
B32: ② "을"은 근로계약 기간 동안 근로자는 회사나 회사 고객의 비밀정보를 입수하여서는 아니 되며 근로계약 중이거나 계약이 종결된
B33: 후에도 이러한 정보를 엄격하게 비밀로 취급한다는 것과 제3자에게 그러한 비밀정보를 공개하지 않겠다는 것을 서약한다.
A34: 계약해지사유 | B34: ① “갑”의 취업규칙 또는 기타 사규 및 방침(안전보건 및 위생규칙 등)을 위반했을 경우
B35: ② 무단지각, 조퇴, 외출 및 결근을 했을 경우
B36: ③ “갑”의 물품(식자재 등)을 “갑”의 승인 없이 반출 또는 반출하려고 했을 경우
B37: ④ “갑”의 신뢰 및 명예를 훼손시킨 경우 (예: 고객과의 불필요한 마찰을 일으킨 경우)
B38: ⑤ 사업장의 질서를 문란하거나 고객 및 협력업체 등으로부터 금품을 수수하거나 향응을 제공받은 경우
B39: ⑥ 형법상 범죄행위에 해당되는 행위를 한 경우
B40: ⑦ "갑"의 정당한 업무지시를 거부 또는 위배한 경우
B41: ⑧ 기타 이에 준하는 사유로서 사회통념상 근로계약을 존속시킬 수 없는 정도의 사유
...

Sheet 임금명세서
A1: 1 | I1: =A1+1 -> 2 | Q1: =I1+1 -> 3 | Y1: =Q1+1 -> 4 | AG1: =Y1+1 -> 5 | AO1: =AG1+1 -> 6 | AW1: =AO1+1 -> 7
A3: 임 금 명 세 서 | I3: 임 금 명 세 서 | Q3: 임 금 명 세 서 | Y3: 임 금 명 세 서 | AG3: 임 금 명 세 서 | AO3: 임 금 명 세 서 | AW3: 임 금 명 세 서
A5: 회사명 | C5: =급여대장!$A$4 -> 제이엠건축인테리어 주식회사 | I5: 회사명 | K5: =급여대장!$A$4 -> 제이엠건축인테리어 주식회사 | Q5: 회사명 | S5: =급여대장!$A$4 -> 제이엠건축인테리어 주식회사 | Y5: 회사명 | AA5: =급여대장!$A$4 -> 제이엠건축인테리어 주식회사 | AG5: 회사명 | AI5: =급여대장!$A$4 -> 제이엠건축인테리어 주식회사 | AO5: 회사명 | AQ5: =급여대장!$A$4 -> 제이엠건축인테리어 주식회사 | AW5: 회사명 | AY5: =급여대장!$A$4 -> 제이엠건축인테리어 주식회사
A6: 급여귀속 | C6: =급여대장!$AD$3 -> 46082 | E6: 지급일 | G6: =급여대장!$AD$4 -> 매월 5일 | I6: 급여귀속 | K6: =급여대장!$AD$3 -> 46082 | M6: 지급일 | O6: =급여대장!$AD$4 -> 매월 5일 | Q6: 급여귀속 | S6: =급여대장!$AD$3 -> 46082 | U6: 지급일 | W6: =급여대장!$AD$4 -> 매월 5일 | Y6: 급여귀속 | AA6: =급여대장!$AD$3 -> 46082 | AC6: 지급일 | AE6: =급여대장!$AD$4 -> 매월 5일 | AG6: 급여귀속 | AI6: =급여대장!$AD$3 -> 46082 | AK6: 지급일 | AM6: =급여대장!$AD$4 -> 매월 5일 | AO6: 급여귀속 | AQ6: =급여대장!$AD$3 -> 46082 | AS6: 지급일 | AU6: =급여대장!$AD$4 -> 매월 5일 | AW6: 급여귀속 | AY6: =급여대장!$AD$3 -> 46082 | BA6: 지급일 | BC6: =급여대장!$AD$4 -> 매월 5일
A7: 성명 | C7: =VLOOKUP(A1,급여대장!$A$6:$B$10,2,0) -> 이소연 | E7: 입사일 | G7: =급여대장!E6 -> 2024.11.01 | I7: 성명 | K7: =VLOOKUP(I1,급여대장!$A$6:$B$10,2,0) -> 문준호 | M7: 입사일 | O7: =급여대장!E7 -> 2023.09.04 | Q7: 성명 | S7: =VLOOKUP(Q1,급여대장!$A$6:$B$10,2,0) -> 하동명 | U7: 입사일 | W7: =급여대장!E8 -> 2025.08.04 | Y7: 성명 | AA7: =VLOOKUP(Y1,급여대장!$A$6:$B$10,2,0) -> 정휘범 | AC7: 입사일 | AE7: =급여대장!E9 -> 2025.03.24 | AG7: 성명 | AI7: =VLOOKUP(AG1,급여대장!$A$6:$B$10,2,0) -> 0 | AK7: 입사일 | AM7: =급여대장!E10 -> 0 | AO7: 성명 | AQ7: =VLOOKUP(AO1,급여대장!$A$6:$B$11,2,0) -> 0 | AS7: 입사일 | AU7: =급여대장!E11 -> 0 | AW7: 성명 | AY7: =VLOOKUP(AW1,급여대장!$A$6:$B$12,2,0) -> 0 | BA7: 입사일 | BC7: =급여대장!E12 -> 0
A8: 세부 내역 | I8: 세부 내역 | Q8: 세부 내역 | Y8: 세부 내역 | AG8: 세부 내역 | AO8: 세부 내역 | AW8: 세부 내역
A10: 지 급 | E10: 공 제 | I10: 지 급 | M10: 공 제 | Q10: 지 급 | U10: 공 제 | Y10: 지 급 | AC10: 공 제 | AG10: 지 급 | AK10: 공 제 | AO10: 지 급 | AS10: 공 제 | AW10: 지 급 | BA10: 공 제
A11: 임금항목 | C11: 지급금액(원) | E11: 공제 항목 | G11: 공제금액(원) | I11: 임금항목 | K11: 지급금액(원) | M11: 공제 항목 | O11: 공제금액(원) | Q11: 임금항목 | S11: 지급금액(원) | U11: 공제 항목 | W11: 공제금액(원) | Y11: 임금항목 | AA11: 지급금액(원) | AC11: 공제 항목 | AE11: 공제금액(원) | AG11: 임금항목 | AI11: 지급금액(원) | AK11: 공제 항목 | AM11: 공제금액(원) | AO11: 임금항목 | AQ11: 지급금액(원) | AS11: 공제 항목 | AU11: 공제금액(원) | AW11: 임금항목 | AY11: 지급금액(원) | BA11: 공제 항목 | BC11: 공제금액(원)
A12: 매월 지급 | B12: 기본급 | C12: =VLOOKUP(A1,급여대장!$A$6:$AD$10,7,0) -> 6475000 | E12: 건강보험 | G12: =VLOOKUP(A1,급여대장!$A$6:$AD$10,16,0) -> 247150 | I12: 매월 지급 | J12: 기본급 | K12: =VLOOKUP(I1,급여대장!$A$6:$AD$10,7,0) -> 6875000 | M12: 건강보험 | O12: =VLOOKUP(I1,급여대장!$A$6:$AD$10,16,0) -> 247690 | Q12: 매월 지급 | R12: 기본급 | S12: =VLOOKUP(Q1,급여대장!$A$6:$AD$10,7,0) -> 2834021.3 | U12: 건강보험 | W12: =VLOOKUP(Q1,급여대장!$A$6:$AD$10,16,0) -> 122230 | Y12: 매월 지급 | Z12: 기본급 | AA12: =VLOOKUP(Y1,급여대장!$A$6:$AD$10,7,0) -> 505001 | AC12: 건강보험 | AE12: =VLOOKUP(Y1,급여대장!$A$6:$AD$10,16,0) -> 0 | AG12: 매월 지급 | AH12: 기본급 | AI12: =VLOOKUP(AG1,급여대장!$A$6:$AD$10,7,0) | AK12: 건강보험 | AM12: =VLOOKUP(AG1,급여대장!$A$6:$AD$10,16,0) -> 0 | AO12: 매월 지급 | AP12: 기본급 | AQ12: =VLOOKUP(AO1,급여대장!$A$6:$AD$11,7,0) -> 0 | AS12: 건강보험 | AU12: =VLOOKUP(AO1,급여대장!$A$1:$AD$11,16,0) -> 0 | AW12: 매월 지급 | AX12: 기본급 | AY12: =VLOOKUP(AW1,급여대장!$A$6:$AD$12,7,0) | BA12: 건강보험 | BC12: =VLOOKUP(AW1,급여대장!$A$6:$AD$12,16,0) -> 0
B13: 식대 | C13: =VLOOKUP(A1,급여대장!$A$6:$AD$10,8,0) -> 200000 | E13: 요양보험 | G13: =VLOOKUP(A1,급여대장!$A$6:$AD$10,17,0) -> 32470 | J13: 식대 | K13: =VLOOKUP(I1,급여대장!$A$6:$AD$10,8,0) -> 0 | M13: 요양보험 | O13: =VLOOKUP(I1,급여대장!$A$6:$AD$10,17,0) -> 32540 | R13: 식대 | S13: =VLOOKUP(Q1,급여대장!$A$6:$AD$10,8,0) -> 200000 | U13: 요양보험 | W13: =VLOOKUP(Q1,급여대장!$A$6:$AD$10,17,0) -> 16060 | Z13: 식대 | AA13: =VLOOKUP(Y1,급여대장!$A$6:$AD$10,8,0) -> 51613 | AC13: 요양보험 | AE13: =VLOOKUP(Y1,급여대장!$A$6:$AD$10,17,0) -> 0 | AH13: 식대 | AI13: =VLOOKUP(AG1,급여대장!$A$6:$AD$10,8,0) -> 0 | AK13: 요양보험 | AM13: =VLOOKUP(AG1,급여대장!$A$6:$AD$10,17,0) -> 0 | AP13: 식대 | AQ13: =VLOOKUP(AO1,급여대장!$A$6:$AD$11,8,0) -> 0 | AS13: 요양보험 | AU13: =VLOOKUP(AO1,급여대장!$A$6:$AD$11,17,0) -> 0 | AX13: 식대 | AY13: =VLOOKUP(AW1,급여대장!$A$6:$AD$12,8,0) -> 0 | BA13: 요양보험 | BC13: =VLOOKUP(AW1,급여대장!$A$6:$AD$12,17,0) -> 0
B14: 차량유지비 | C14: =VLOOKUP(A1,급여대장!$A$6:$AD$10,9,0) -> 200000 | E14: 국민연금 | G14: =VLOOKUP(A1,급여대장!$A$6:$AD$10,18,0) -> 302570 | J14: 차량유지비 | K14: =VLOOKUP(I1,급여대장!$A$6:$AD$10,9,0) -> 0 | M14: 국민연금 | O14: =VLOOKUP(I1,급여대장!$A$6:$AD$10,18,0) -> 302570 | R14: 차량유지비 | S14: =VLOOKUP($Q$1,급여대장!$A$6:$AD$10,9,0) -> 0 | U14: 국민연금 | W14: =VLOOKUP(Q1,급여대장!$A$6:$AD$10,18,0) -> 161500 | Z14: 차량유지비 | AA14: =VLOOKUP(Y1,급여대장!$A$6:$AD$10,9,0) -> 0 | AC14: 국민연금 | AE14: =VLOOKUP(Y1,급여대장!$A$6:$AD$10,18,0) -> 0 | AH14: 차량유지비 | AI14: =VLOOKUP(AG1,급여대장!$A$6:$AD$10,9,0) -> 0 | AK14: 국민연금 | AM14: =VLOOKUP(AG1,급여대장!$A$6:$AD$10,18,0) -> 0 | AP14: 차량유지비 | AQ14: =VLOOKUP(AO1,급여대장!$A$6:$AD$11,9,0) -> 0 | AS14: 국민연금 | AU14: =VLOOKUP(AO1,급여대장!$A$6:$AD$11,18,0) -> 0 | AX14: 차량유지비 | AY14: =VLOOKUP(AW1,급여대장!$A$6:$AD$12,9,0) -> 0 | BA14: 국민연금 | BC14: =VLOOKUP(AW1,급여대장!$A$6:$AD$12,18,0) -> 0
B15: 연장수당 | C15: =VLOOKUP(A1,급여대장!$A$6:$AD$10,10,0) -> 0 | E15: 고용보험 | G15: =VLOOKUP(A1,급여대장!$A$6:$AD$10,19,0) -> 0 | J15: 연장수당 | K15: =VLOOKUP(I1,급여대장!$A$6:$AD$10,10,0) -> 0 | M15: 고용보험 | O15: =VLOOKUP(I1,급여대장!$A$6:$AD$10,19,0) -> 0 | R15: 연장수당 | S15: =VLOOKUP($Q$1,급여대장!$A$6:$AD$10,10,0) -> 899318.74 | U15: 고용보험 | W15: =VLOOKUP(Q1,급여대장!$A$6:$AD$10,19,0) -> 33600 | Z15: 연장수당 | AA15: =VLOOKUP(Y1,급여대장!$A$6:$AD$10,10,0) -> 86788 | AC15: 고용보험 | AE15: =VLOOKUP(Y1,급여대장!$A$6:$AD$10,19,0) -> 0 | AH15: 연장수당 | AI15: =VLOOKUP(AG1,급여대장!$A$6:$AD$10,10,0) | AK15: 고용보험 | AM15: =VLOOKUP(AG1,급여대장!$A$6:$AD$10,19,0) -> 0 | AP15: 연장수당 | AQ15: =VLOOKUP(AO1,급여대장!$A$6:$AD$11,10,0) -> 0 | AS15: 고용보험 | AU15: =VLOOKUP(AO1,급여대장!$A$6:$AD$11,19,0) -> 0 | AX15: 연장수당 | AY15: =VLOOKUP(AW1,급여대장!$A$6:$AD$12,10,0) | BA15: 고용보험 | BC15: =VLOOKUP(AW1,급여대장!$A$6:$AD$12,19,0) -> 0
B16: 연장추가수당 | C16: =VLOOKUP(A1,급여대장!$A$6:$AD$10,11,0) -> 0 | E16: 소득세 | G16: =VLOOKUP(A1,급여대장!$A$6:$AD$10,20,0) -> 562470 | J16: 연장추가수당 | K16: =VLOOKUP(I1,급여대장!$A$6:$AD$10,11,0) -> 0 | M16: 소득세 | O16: =VLOOKUP(I1,급여대장!$A$6:$AD$10,20,0) -> 657220 | R16: 연장추가수당 | S16: =VLOOKUP(Q1,급여대장!$A$6:$AD$10,11,0) -> 0 | U16: 소득세 | W16: =VLOOKUP(Q1,급여대장!$A$6:$AD$10,20,0) -> 154110 | Z16: 연장추가수당 | AA16: =VLOOKUP(Y1,급여대장!$A$6:$AD$10,11,0) -> 0 | AC16: 소득세 | AE16: =VLOOKUP(Y1,급여대장!$A$6:$AD$10,20,0) -> 0 | AH16: 연장추가수당 | AI16: =VLOOKUP(AG1,급여대장!$A$6:$AD$10,11,0) | AK16: 소득세 | AM16: =VLOOKUP(AG1,급여대장!$A$6:$AD$10,20,0) -> 0 | AP16: 연장추가수당 | AQ16: =VLOOKUP(AO1,급여대장!$A$6:$AD$11,11,0) | AS16: 소득세 | AU16: =VLOOKUP(AO1,급여대장!$A$6:$AD$11,20,0) -> 0 | AX16: 연장추가수당 | AY16: =VLOOKUP(AW1,급여대장!$A$6:$AD$12,11,0) | BA16: 소득세 | BC16: =VLOOKUP(AW1,급여대장!$A$6:$AD$12,20,0) -> 0
E17: 주민세 | G17: =VLOOKUP(A1,급여대장!$A$6:$AD$10,21,0) -> 56240 | J17: 직책수당 | K17: =VLOOKUP(I1,급여대장!$A$6:$AD$10,12,0) -> 15000 | M17: 주민세 | O17: =VLOOKUP(I1,급여대장!$A$6:$AD$10,21,0) -> 65720 | U17: 주민세 | W17: =VLOOKUP(Q1,급여대장!$A$6:$AD$10,21,0) -> 15410 | AC17: 주민세 | AE17: =VLOOKUP(Y1,급여대장!$A$6:$AD$10,21,0) -> 0 | AK17: 주민세 | AM17: =VLOOKUP(AG1,급여대장!$A$6:$AD$10,21,0) -> 0 | AS17: 주민세 | AU17: =VLOOKUP(AO1,급여대장!$A$6:$AD$11,21,0) -> 0 | BA17: 주민세 | BC17: =VLOOKUP(AW1,급여대장!$A$6:$AD$12,21,0) -> 0
M18: 건강보험 정산 | O18: =급여대장!Y7 -> 0 | U18: 건강보험 정산 | W18: =급여대장!Y8 -> 0 | AC18: 프로그램 공제 | AE18: =VLOOKUP(Y1,급여대장!$A$6:$AD$10,23,0) -> 0 | AS18: 건강보험 정산
M19: 장기요양 정산 | O19: =급여대장!Z7 -> 0 | U19: 장기요양 정산 | W19: =급여대장!Z8 -> 0 | AS19: 장기요양 정산
A22: 격월 또는부정기 지급 | B22: 상여금 | C22: =VLOOKUP(A1,급여대장!$A$6:$AD$10,13,0) -> 0 | I22: 격월 또는부정기 지급 | J22: 상여금 | K22: =VLOOKUP(I1,급여대장!$A$6:$AD$10,13,0) -> 0 | Q22: 격월 또는부정기 지급 | R22: 상여금 | S22: =VLOOKUP(Q1,급여대장!$A$6:$AD$10,13,0) -> 0 | U22: =323000/2 -> 161500 | Y22: 격월 또는부정기 지급 | Z22: 상여금 | AA22: =VLOOKUP(Y1,급여대장!$A$6:$AD$10,13,0) -> 0 | AG22: 격월 또는부정기 지급 | AH22: 상여금 | AI22: =VLOOKUP(AG1,급여대장!$A$6:$AD$10,13,0) -> 0 | AO22: 격월 또는부정기 지급 | AP22: 상여금 | AQ22: =VLOOKUP(AO1,급여대장!$A$6:$AD$11,13,0) -> 0 | AW22: 격월 또는부정기 지급 | AX22: 상여금 | AY22: =VLOOKUP(AW1,급여대장!$A$6:$AD$12,13,0) -> 0
A25: 지 급 액 계 | C25: =SUM(C12:D24) -> 6875000 | E25: 공 제 액 계 | G25: =SUM(G12:H24) -> 1200900 | I25: 지 급 액 계 | K25: =SUM(K12:L24) -> 6890000 | M25: 공 제 액 계 | O25: =SUM(O12:P24) -> 1305740 | Q25: 지 급 액 계 | S25: =SUM(S12:T24) -> 3933340 | U25: 공 제 액 계 | W25: =SUM(W12:X19) -> 502910 | Y25: 지 급 액 계 | AA25: =SUM(AA12:AB24) -> 643402 | AC25: 공 제 액 계 | AE25: =SUM(AE12:AF24) -> 0 | AG25: 지 급 액 계 | AI25: =SUM(AI12:AJ24) -> 0 | AK25: 공 제 액 계 | AM25: =SUM(AM12:AN24) -> 0 | AO25: 지 급 액 계 | AQ25: =SUM(AQ12:AR24) -> 0 | AS25: 공 제 액 계 | AU25: =SUM(AU12:AV24) -> 0 | AW25: 지 급 액 계 | AY25: =SUM(AY12:AZ24) -> 0 | BA25: 공 제 액 계 | BC25: =SUM(BC12:BD24) -> 0
E26: 실수령액(원) | G26: =C25-G25 -> 5674100 | M26: 실수령액(원) | O26: =K25-O25 -> 5584260 | U26: 실수령액(원) | W26: =S25-W25 -> 3430430 | AC26: 실수령액(원) | AE26: =AA25-AE25 -> 643402 | AK26: 실수령액(원) | AM26: =AI25-AM25 -> 0 | AS26: 실수령액(원) | AU26: =AQ25-AU25 -> 0 | BA26: 실수령액(원) | BC26: =AY25-BC25 -> 0
A27: 계 산 방 법 | I27: 계 산 방 법 | Q27: 계 산 방 법 | Y27: 계 산 방 법 | AG27: 계 산 방 법 | AO27: 계 산 방 법 | AW27: 계 산 방 법
A28: 구분 | C28: 산출식 또는 산출방법 | G28: 지급액(원) | I28: 구분 | K28: 산출식 또는 산출방법 | O28: 지급액(원) | Q28: 구분 | S28: 산출식 또는 산출방법 | W28: 지급액(원) | Y28: 구분 | AA28: 산출식 또는 산출방법 | AE28: 지급액(원) | AG28: 구분 | AI28: 산출식 또는 산출방법 | AM28: 지급액(원) | AO28: 구분 | AQ28: 산출식 또는 산출방법 | AU28: 지급액(원) | AW28: 구분 | AY28: 산출식 또는 산출방법 | BC28: 지급액(원)
A29: 기본급 | C29: 통상시급 x 209시간 | G29: =C12 -> 6475000 | I29: 기본급 | K29: 통상시급 x 209시간 | O29: =K12 -> 6875000 | Q29: 기본급 | S29: 통상시급 x 209시간 | W29: =S12 -> 2834021.3 | Y29: 기본급 | AA29: 기본급 / 31일 x 8일 | AE29: =AA12 -> 505001 | AG29: 기본급 | AI29: 통상시급 x 209시간 | AM29: =AI12 | AO29: 기본급 | AQ29: 통상시급 x 28일 /6일 | AU29: =AQ12 -> 0 | AW29: 기본급 | AY29: 통상시급 x 209시간 | BC29: =AY12
A30: 연장수당 | C30: 통상시급x | E30: =VLOOKUP(A1,'[15]포괄 급여계산'!$A$3:$AG$42,18,0) -> 0 | F30: 시간 | G30: =C15 -> 0 | I30: 연장수당 | K30: 통상시급x | M30: =VLOOKUP(I1,'포괄 급여계산'!$A$3:$AG$12,18,0) -> 0 | N30: 시간 | O30: =K15 -> 0 | Q30: 연장수당 | S30: 통상시급x | U30: =VLOOKUP(Q1,'포괄 급여계산'!$A$3:$AG$12,18,0) -> 61.95 | V30: 시간 | W30: =S15 -> 899318.74 | Y30: 연장수당 | AA30: 기본급 / 31일 x 8일 | AE30: =AA15 -> 86788 | AG30: 연장수당 | AI30: 통상시급x | AK30: =VLOOKUP(AG1,'포괄 급여계산'!$A$3:$AG$12,18,0) | AL30: 시간 | AM30: =AI15 | AO30: 연장수당 | AQ30: 통상시급 x 28일 /6일 | AU30: =AQ15 -> 0 | AW30: 연장수당 | AY30: 통상시급x | BA30: =VLOOKUP(AW1,'포괄 급여계산'!$A$3:$AG$12,18,0) | BB30: 시간 | BC30: =AY15
A31: 연장추가수당 | C31: 통상시급x | E31: =VLOOKUP(A1,'[15]포괄 급여계산'!$A$3:$AG$42,19,0) -> 0 | F31: 시간 | G31: =C16 -> 0 | I31: 연장추가수당 | K31: 통상시급x | M31: =VLOOKUP(I1,'포괄 급여계산'!$A$3:$AG$12,19,0) -> 0 | N31: 시간 | O31: =K16 -> 0 | Q31: 연장추가수당 | S31: 통상시급x | U31: =VLOOKUP(Q1,'포괄 급여계산'!$A$3:$AG$12,19,0) -> 0 | V31: 시간 | W31: =S16 -> 0 | Y31: 연장추가수당 | AA31: 통상시급x | AC31: =VLOOKUP(Y1,'포괄 급여계산'!$A$3:$AG$12,19,0) -> 0 | AD31: 시간 | AE31: =AA16 -> 0 | AG31: 연장추가수당 | AI31: 통상시급x | AK31: =VLOOKUP(AG1,'포괄 급여계산'!$A$3:$AG$12,19,0) -> 0 | AL31: 시간 | AM31: =AI16 | AO31: 연장추가수당 | AQ31: 통상시급x | AS31: =VLOOKUP(AO1,'포괄 급여계산'!$A$3:$AG$12,19,0) -> 0 | AT31: 시간 | AU31: =AQ16 | AW31: 연장추가수당 | AY31: 통상시급x | BA31: =VLOOKUP(AW1,'포괄 급여계산'!$A$3:$AG$12,19,0) -> 0 | BB31: 시간 | BC31: =AY16
A33: 귀하에 노고에 감사드립니다. | I33: 귀하에 노고에 감사드립니다. | Q33: 귀하에 노고에 감사드립니다. | Y33: 귀하에 노고에 감사드립니다. | AG33: 귀하에 노고에 감사드립니다. | AO33: 귀하에 노고에 감사드립니다. | AW33: 귀하에 노고에 감사드립니다.

Sheet 근로계약서(상용)
A1: 근 로 계 약 서 | M1: 4
A3: =급여셋팅!$D$14 -> 제이엠건축인테리어 주식회사 | C3: (이하 "갑"이라고 한다)와 | E3: =VLOOKUP($M$1,'포괄 급여계산'!$A$3:$AG$12,2,0) -> 정휘범 | F3: (이하 "을"이라고 한다)은/는 근로계약을 체결하고 상호 성실히 이행한다.
A4: 근로계약기간 수습기간 | B4: ① 근로계약기간은 | C4: =VLOOKUP($M$1,'포괄 급여계산'!$A$3:$AG$12,5,0) -> 2025.03.24 | D4: 부터 퇴직시까지로 한다.
B5: ② 입사일로부터 | D5: 까지 수습기간으로 하며 해당 기간 중 임금은 법률이 정하는 바에 의하여
B6: 조절하여 지급할 수 있다.
B7: ③ 수습기간 만료 후 채용여부를 결정하되 수습기간 중 본인근무실태, 성실성, 근면성 등을 평가하여 부적격하다고 판단될 때에는
B8: 수습기간 중이라도 본 계약을 취소할 수 있다.
A9: 근무장소 담당 업무 | B9: ① 근로장소: | C9: =VLOOKUP($M$1,'포괄 급여계산'!$A$3:$AG$12,8,0) -> 본사 | E9: 또는 "갑"이 지정한 장소.
B10: ② 담당업무: | C10: =VLOOKUP($M$1,'포괄 급여계산'!$A$3:$AG$12,9,0) -> 디자인 | E10: 및 그와 관련된 업무로 한다.
B11: ③ "갑"은 필요한 경우 전 2항에서 정한 근로장소 및 업무의 내용을 변경할 수 있으며 "을"은 정당한 이유가 없는 한 이에 응해야한다.
A12: 근로시간 휴게시간 | B12: ① 소정근로시간 : | C12: =VLOOKUP($M$1,'포괄 급여계산'!$A$3:$AC$12,14,0) -> 0.375 | D12: 부터 | E12: =VLOOKUP($M$1,'포괄 급여계산'!$A$3:$AC$12,15,0) -> 0.75 | F12: 까지
B13: ② 휴게시간 : | C13: 시작 | D13: =VLOOKUP($M$1,'포괄 급여계산'!$A$3:$AC$12,16,0) -> 0.5 | E13: 종료 | F13: =VLOOKUP($M$1,'포괄 급여계산'!$A$3:$AC$12,17,0) -> 0.54166667
B14: ③ 전 2항의 근로시간 및 휴게시간은 "갑"의 사정에 따라 필요한 경우 이를 변경하여 운영할 수 있다.
A15: 근로일 및 휴일 | B15: ① 소정근로일은 | C15: =VLOOKUP($M$1,'포괄 급여계산'!$A$3:$AC$12,10,0) -> 월~금 | D15: 이며 일요일은 무급휴무일로 한다.
B16: ② 다음 각 호의 1에 정하는 날은 유급휴일로 한다. 다만, "을"이 1주 동안에 소정근로일을 개근하지 아니한 경우 주휴일은 무급으로 하며
B17: 각 호의 휴일이 중복되는 경우에는 하나의 휴일로 취급한다.
B18: 1. 주휴일(일요일) 2. 근로자의 날(매년 5월 1일) 3. 기타 회사에서 정한 날
B19: ③ 전 2항의 근로일과 주휴일은 "갑"의 사정에 따라 필요한 경우 이를 변경할 수 있으며 각 사업장의 상황에 따라 일요일이 아닌 근로일에
B20: 쉬는 경우에는 주휴일을 사용한 것으로 갈음한다. 또한 업무상 필요한 경우 휴일을 해당 직원에게 24시간 전에 미리 통보하여 다른 날로
B21: 부여할 수 있다. 이 경우 “갑”은 휴일근로수당의 지급의무를 면한다. | AC21: 1
A22: 연장·휴일 및 야간근로 | B22: ① “갑”은 “을”의 동의를 받아 시간외(연장,야간,휴일)근로를 명할 수 있다.
B23: ② 시간외(연장,야간,휴일)근로는 원칙적으로 상사의 명령 또는 상사의 사전승인을 득한 경우에만 인정된다.
B24: ③ "갑"은 근로자대표와의 서면합의에 따라 연장•야간•휴일근로에 대하여 임금을 지급하는 것을 갈음하여 휴가를 줄 수 있다.
A25: 임금 | B25: “을”의 급여내역은 연봉계약서에 의한다.
A26: 연차휴가 | B26: ① 1년간 80퍼센트 이상 출근한 직원에게는 15일의 유급휴가를 주며 계속근로연수가 1년 미만인 직원 또는 1년간 80퍼센트 미만
B27: 출근한 직원에 대하여는 1월간 개근 시 1일의 유급휴가를 준다.
B28: ② 기타 연차 유급휴가에 관한 사항은 취업규칙 및 근로기준법에서 정하는 바에 따른다.
B29: ③ 착공 및 조기준공 등등을 포함하여 공사현장에 따라 불가피하게 휴무가 발생 한 경우 연차사용으로 대체 할 수 있다.
A30: 비밀준수의무 | B30: ①"을"이 근무 중 고의 또는 과실로 "갑"에게 손해를 끼치거나 본인이나 타인의 임금내역을 고의∙과실로 공개 또는 누설하는 경우에는
B31: 징계와 더불어 손해배상 등 민∙형사상의 책임을 물을 수 있다
B32: ② "을"은 근로계약 기간 동안 근로자는 회사나 회사 고객의 비밀정보를 입수하여서는 아니 되며 근로계약 중이거나 계약이 종결된
B33: 후에도 이러한 정보를 엄격하게 비밀로 취급한다는 것과 제3자에게 그러한 비밀정보를 공개하지 않겠다는 것을 서약한다.
A34: 계약해지사유 | B34: ① “갑”의 취업규칙 또는 기타 사규 및 방침(안전보건 및 위생규칙 등)을 위반했을 경우
B35: ② 무단지각, 조퇴, 외출 및 결근을 했을 경우
B36: ③ “갑”의 물품(식자재 등)을 “갑”의 승인 없이 반출 또는 반출하려고 했을 경우
B37: ④ “갑”의 신뢰 및 명예를 훼손시킨 경우 (예: 고객과의 불필요한 마찰을 일으킨 경우)
B38: ⑤ 사업장의 질서를 문란하거나 고객 및 협력업체 등으로부터 금품을 수수하거나 향응을 제공받은 경우
B39: ⑥ 형법상 범죄행위에 해당되는 행위를 한 경우
B40: ⑦ "갑"의 정당한 업무지시를 거부 또는 위배한 경우
B41: ⑧ 기타 이에 준하는 사유로서 사회통념상 근로계약을 존속시킬 수 없는 정도의 사유
...

Sheet 근로계약서(현장)
A1: 근 로 계 약 서 | M1: 5
A3: =급여셋팅!$D$14 -> 제이엠건축인테리어 주식회사 | C3: (이하 "갑"이라고 한다)와 | E3: =VLOOKUP($M$1,'포괄 급여계산'!$A$3:$AG$12,2,0) -> 0 | F3: (이하 "을"이라고 한다)은/는 근로계약을 체결하고 상호 성실히 이행한다.
A4: 근로계약기간 수습기간 | B4: ① 근로계약기간은 | C4: =VLOOKUP($M$1,'포괄 급여계산'!$A$3:$AG$12,5,0) -> 0 | D4: 부터 퇴직시까지로 한다.
B5: ② 입사일로부터 | D5: 까지 수습기간으로 하며 해당 기간 중 임금은 법률이 정하는 바에 의하여
B6: 조절하여 지급할 수 있다.
B7: ③ 수습기간 만료 후 채용여부를 결정하되 수습기간 중 본인근무실태, 성실성, 근면성 등을 평가하여 부적격하다고 판단될 때에는
B8: 수습기간 중이라도 본 계약을 취소할 수 있다.
A9: 근무장소 담당 업무 | B9: ① 근로장소: | C9: =VLOOKUP($M$1,'포괄 급여계산'!$A$3:$AG$12,8,0) -> 0 | E9: 또는 "갑"이 지정한 장소.
B10: ② 담당업무: | C10: =VLOOKUP($M$1,'포괄 급여계산'!$A$3:$AG$12,9,0) -> 0 | E10: 및 그와 관련된 업무로 한다.
B11: ③ "갑"은 필요한 경우 전 2항에서 정한 근로장소 및 업무의 내용을 변경할 수 있으며 "을"은 정당한 이유가 없는 한 이에 응해야한다.
A12: 근로시간 휴게시간 | B12: ① 소정근로시간 : | C12: =VLOOKUP($M$1,'포괄 급여계산'!$A$3:$AC$12,14,0) -> #N/A | D12: 부터 | E12: =VLOOKUP($M$1,'포괄 급여계산'!$A$3:$AC$12,15,0) -> #N/A | F12: 까지
B13: ② 휴게시간 : | C13: 시작 | D13: =VLOOKUP($M$1,'포괄 급여계산'!$A$3:$AC$12,16,0) -> #N/A | E13: 종료 | F13: =VLOOKUP($M$1,'포괄 급여계산'!$A$3:$AC$12,17,0) -> #N/A
B14: ③ 전 2항의 근로시간 및 휴게시간은 "갑"의 사정에 따라 필요한 경우 이를 변경하여 운영할 수 있다.
A15: 근로일 및 휴일 | B15: ① 소정근로일은 | C15: =VLOOKUP($M$1,'포괄 급여계산'!$A$3:$AC$12,10,0) -> 0 | D15: 이며 토요일은 격주 근무로 한다.
B16: ② 다음 각 호의 1에 정하는 날은 유급휴일로 한다. 다만, "을"이 1주 동안에 소정근로일을 개근하지 아니한 경우 주휴일은 무급으로 하며
B17: 각 호의 휴일이 중복되는 경우에는 하나의 휴일로 취급한다.
B18: 1. 주휴일(일요일) 2. 근로자의 날(매년 5월 1일) 3. 기타 회사에서 정한 날
B19: ③ 전 2항의 근로일과 주휴일은 "갑"의 사정에 따라 필요한 경우 이를 변경할 수 있으며 각 사업장의 상황에 따라 일요일이 아닌 근로일에
B20: 쉬는 경우에는 주휴일을 사용한 것으로 갈음한다. 또한 업무상 필요한 경우 휴일을 해당 직원에게 24시간 전에 미리 통보하여 다른 날로
B21: 부여할 수 있다. 이 경우 “갑”은 휴일근로수당의 지급의무를 면한다. | AC21: 1
A22: 연장·휴일 및 야간근로 | B22: ① “갑”은 “을”의 동의를 받아 시간외(연장,야간,휴일)근로를 명할 수 있다.
B23: ② 시간외(연장,야간,휴일)근로는 원칙적으로 상사의 명령 또는 상사의 사전승인을 득한 경우에만 인정된다.
B24: ③ "갑"은 근로자대표와의 서면합의에 따라 연장•야간•휴일근로에 대하여 임금을 지급하는 것을 갈음하여 휴가를 줄 수 있다.
A25: 임금 | B25: “을”의 급여내역은 연봉계약서에 의한다.
A26: 연차휴가 | B26: ① 1년간 80퍼센트 이상 출근한 직원에게는 15일의 유급휴가를 주며 계속근로연수가 1년 미만인 직원 또는 1년간 80퍼센트 미만
B27: 출근한 직원에 대하여는 1월간 개근 시 1일의 유급휴가를 준다.
B28: ② 기타 연차 유급휴가에 관한 사항은 취업규칙 및 근로기준법에서 정하는 바에 따른다.
B29: ③ 착공 및 조기준공 등등을 포함하여 공사현장에 따라 불가피하게 휴무가 발생 한 경우 연차사용으로 대체 할 수 있다.
A30: 비밀준수의무 | B30: ①"을"이 근무 중 고의 또는 과실로 "갑"에게 손해를 끼치거나 본인이나 타인의 임금내역을 고의∙과실로 공개 또는 누설하는 경우에는
B31: 징계와 더불어 손해배상 등 민∙형사상의 책임을 물을 수 있다
B32: ② "을"은 근로계약 기간 동안 근로자는 회사나 회사 고객의 비밀정보를 입수하여서는 아니 되며 근로계약 중이거나 계약이 종결된
B33: 후에도 이러한 정보를 엄격하게 비밀로 취급한다는 것과 제3자에게 그러한 비밀정보를 공개하지 않겠다는 것을 서약한다.
A34: 계약해지사유 | B34: ① “갑”의 취업규칙 또는 기타 사규 및 방침(안전보건 및 위생규칙 등)을 위반했을 경우
B35: ② 무단지각, 조퇴, 외출 및 결근을 했을 경우
B36: ③ “갑”의 물품(식자재 등)을 “갑”의 승인 없이 반출 또는 반출하려고 했을 경우
B37: ④ “갑”의 신뢰 및 명예를 훼손시킨 경우 (예: 고객과의 불필요한 마찰을 일으킨 경우)
B38: ⑤ 사업장의 질서를 문란하거나 고객 및 협력업체 등으로부터 금품을 수수하거나 향응을 제공받은 경우
B39: ⑥ 형법상 범죄행위에 해당되는 행위를 한 경우
B40: ⑦ "갑"의 정당한 업무지시를 거부 또는 위배한 경우
B41: ⑧ 기타 이에 준하는 사유로서 사회통념상 근로계약을 존속시킬 수 없는 정도의 사유
...

Sheet 간이세액표
A1: 2023.02.28부터 적용
N2: (단위 : 원)
A3: 월급여액(천원) [비과세 및 학자금 제외］ | D3: 1 | E3: 2 | F3: 3 | G3: 4 | H3: 5 | I3: 6 | J3: 7 | K3: 8 | L3: 9 | M3: 10 | N3: 11
A5: 이상 | B5: 미만 | F5: 일반 | G5: 일반 | H5: 일반 | I5: 일반 | J5: 일반 | K5: 일반 | L5: 일반 | M5: 일반 | N5: 일반
A6: 770 | B6: 775 | C6: 770000 | D6: 0 | E6: 0 | F6: 0 | G6: 0 | H6: 0 | I6: 0 | J6: 0 | K6: 0 | L6: 0 | M6: 0 | N6: 0 | O6: =#REF! -> #REF!
A7: 775 | B7: 780 | C7: 775000 | D7: 0 | E7: 0 | F7: 0 | G7: 0 | H7: 0 | I7: 0 | J7: 0 | K7: 0 | L7: 0 | M7: 0 | N7: 0 | O7: 0
A8: 780 | B8: 785 | C8: 780000 | D8: 0 | E8: 0 | F8: 0 | G8: 0 | H8: 0 | I8: 0 | J8: 0 | K8: 0 | L8: 0 | M8: 0 | N8: 0 | O8: 0
A9: 785 | B9: 790 | C9: 785000 | D9: 0 | E9: 0 | F9: 0 | G9: 0 | H9: 0 | I9: 0 | J9: 0 | K9: 0 | L9: 0 | M9: 0 | N9: 0 | O9: 0
A10: 790 | B10: 795 | C10: 790000 | D10: 0 | E10: 0 | F10: 0 | G10: 0 | H10: 0 | I10: 0 | J10: 0 | K10: 0 | L10: 0 | M10: 0 | N10: 0 | O10: 0
A11: 795 | B11: 800 | C11: 795000 | D11: 0 | E11: 0 | F11: 0 | G11: 0 | H11: 0 | I11: 0 | J11: 0 | K11: 0 | L11: 0 | M11: 0 | N11: 0 | O11: 0
A12: 800 | B12: 805 | C12: 800000 | D12: 0 | E12: 0 | F12: 0 | G12: 0 | H12: 0 | I12: 0 | J12: 0 | K12: 0 | L12: 0 | M12: 0 | N12: 0 | O12: 0
A13: 805 | B13: 810 | C13: 805000 | D13: 0 | E13: 0 | F13: 0 | G13: 0 | H13: 0 | I13: 0 | J13: 0 | K13: 0 | L13: 0 | M13: 0 | N13: 0 | O13: 0
A14: 810 | B14: 815 | C14: 810000 | D14: 0 | E14: 0 | F14: 0 | G14: 0 | H14: 0 | I14: 0 | J14: 0 | K14: 0 | L14: 0 | M14: 0 | N14: 0 | O14: 0
A15: 815 | B15: 820 | C15: 815000 | D15: 0 | E15: 0 | F15: 0 | G15: 0 | H15: 0 | I15: 0 | J15: 0 | K15: 0 | L15: 0 | M15: 0 | N15: 0 | O15: 0
A16: 820 | B16: 825 | C16: 820000 | D16: 0 | E16: 0 | F16: 0 | G16: 0 | H16: 0 | I16: 0 | J16: 0 | K16: 0 | L16: 0 | M16: 0 | N16: 0 | O16: 0
A17: 825 | B17: 830 | C17: 825000 | D17: 0 | E17: 0 | F17: 0 | G17: 0 | H17: 0 | I17: 0 | J17: 0 | K17: 0 | L17: 0 | M17: 0 | N17: 0 | O17: 0
A18: 830 | B18: 835 | C18: 830000 | D18: 0 | E18: 0 | F18: 0 | G18: 0 | H18: 0 | I18: 0 | J18: 0 | K18: 0 | L18: 0 | M18: 0 | N18: 0 | O18: 0
... A652: 10000 | B652: 10000 | C652: 10000000 | D652: 1507400 | E652: 1431570 | F652: 1200840 | G652: 1170840 | H652: 1140840 | I652: 1110840 | J652: 1080840 | K652: 1050840 | L652: 1020840 | M652: 990840 | N652: 960840 | O652: 940840
A653: 10,000천원 초과 | D653: (10,000,000원인 경우의 해당 세액) + (10,000,000원을 초과하는 금액 중 98%를 곱한 금액의 35% 상당액) + (25,000원)
A654: 14,000천원 이하 | D654: (1천만원인 경우의 해당세액) + (1,397,000원) + (14,000천원을 초과하는 금액 중 98퍼센트를 곱한 금액의 38퍼센트 상당액)
A655: 14,000천원 초과
A656: 28,000천원 이하 | D656: (10,000천원인 경우의 해당세액) + (6,610,600원) + (28,000천원을 초과하는 금액에 98퍼센트를 곱한 금액의 40퍼센트 상당액)
A657: 28,000천원 초과
A658: 30,000천원 이하 | D658: (10,000천원인 경우의 해당세액) + (7,394,600원) + (30,000천원을 초과하는 금액의 40퍼센트 상당액)
A659: 30,000천원 초과
A660: 45,000천원 이하 | D660: (10,000천원인 경우의 해당세액) + (13,394,600원) + (45,000천원을 초과하는 금액의 42퍼센트 상당액)
A661: 45,000천원 초과
D662: (10,000천원인 경우의 해당세액) + (31,034,600원) + (87,000천원을 초과하는 금액의 45퍼센트 상당액)

Sheet 임금명세서 (8~14)
A1: 8 | I1: =A1+1 -> 9 | Q1: =I1+1 -> 10 | Y1: =Q1+1 -> 11 | AG1: =Y1+1 -> 12 | AO1: =AG1+1 -> 13 | AW1: =AO1+1 -> 14
A3: 임 금 명 세 서 | I3: 임 금 명 세 서 | Q3: 임 금 명 세 서 | Y3: 임 금 명 세 서 | AG3: 임 금 명 세 서 | AO3: 임 금 명 세 서 | AW3: 임 금 명 세 서
A5: 회사명 | C5: =급여대장!$A$4 -> 제이엠건축인테리어 주식회사 | I5: 회사명 | K5: =급여대장!$A$4 -> 제이엠건축인테리어 주식회사 | Q5: 회사명 | S5: =급여대장!$A$4 -> 제이엠건축인테리어 주식회사 | Y5: 회사명 | AA5: =급여대장!$A$4 -> 제이엠건축인테리어 주식회사 | AG5: 회사명 | AI5: =급여대장!$A$4 -> 제이엠건축인테리어 주식회사 | AO5: 회사명 | AQ5: =급여대장!$A$4 -> 제이엠건축인테리어 주식회사 | AW5: 회사명 | AY5: =급여대장!$A$4 -> 제이엠건축인테리어 주식회사
A6: 급여귀속 | C6: =급여대장!$AD$3 -> 46082 | E6: 지급일 | G6: =급여대장!$AD$4 -> 매월 5일 | I6: 급여귀속 | K6: =급여대장!$AD$3 -> 46082 | M6: 지급일 | O6: =급여대장!$AD$4 -> 매월 5일 | Q6: 급여귀속 | S6: =급여대장!$AD$3 -> 46082 | U6: 지급일 | W6: =급여대장!$AD$4 -> 매월 5일 | Y6: 급여귀속 | AA6: =급여대장!$AD$3 -> 46082 | AC6: 지급일 | AE6: =급여대장!$AD$4 -> 매월 5일 | AG6: 급여귀속 | AI6: =급여대장!$AD$3 -> 46082 | AK6: 지급일 | AM6: =급여대장!$AD$4 -> 매월 5일 | AO6: 급여귀속 | AQ6: =급여대장!$AD$3 -> 46082 | AS6: 지급일 | AU6: =급여대장!$AD$4 -> 매월 5일 | AW6: 급여귀속 | AY6: =급여대장!$AD$3 -> 46082 | BA6: 지급일 | BC6: =급여대장!$AD$4 -> 매월 5일
A7: 성명 | C7: =VLOOKUP(A1,급여대장!$A$6:$B$13,2,0) -> 0 | E7: 생년월일 | G7: =급여대장!AG13 -> 0 | I7: 성명 | K7: =급여대장!$B$14 -> 0 | M7: 생년월일 | O7: =급여대장!C14 -> 0 | Q7: 성명 | S7: =급여대장!B15 -> 0 | U7: 생년월일 | W7: =급여대장!C15 -> 0 | Y7: 성명 | AA7: =급여대장!#REF! -> #REF! | AC7: 생년월일 | AE7: =급여대장!#REF! -> #REF! | AG7: 성명 | AI7: =급여대장!#REF! -> #REF! | AK7: 생년월일 | AM7: =급여대장!#REF! -> #REF! | AO7: 성명 | AQ7: =VLOOKUP(AO1,급여대장!$A$6:$B$15,2,0) -> #N/A | AS7: 생년월일 | AU7: =급여대장!#REF! -> #REF! | AW7: 성명 | AY7: =VLOOKUP(AW1,급여대장!$A$6:$B$15,2,0) -> #N/A | BA7: 생년월일 | BC7: =급여대장!#REF! -> #REF!
A8: 세부 내역 | I8: 세부 내역 | Q8: 세부 내역 | Y8: 세부 내역 | AG8: 세부 내역 | AO8: 세부 내역 | AW8: 세부 내역
A10: 지 급 | E10: 공 제 | I10: 지 급 | M10: 공 제 | Q10: 지 급 | U10: 공 제 | Y10: 지 급 | AC10: 공 제 | AG10: 지 급 | AK10: 공 제 | AO10: 지 급 | AS10: 공 제 | AW10: 지 급 | BA10: 공 제
A11: 임금항목 | C11: 지급금액(원) | E11: 공제 항목 | G11: 공제금액(원) | I11: 임금항목 | K11: 지급금액(원) | M11: 공제 항목 | O11: 공제금액(원) | Q11: 임금항목 | S11: 지급금액(원) | U11: 공제 항목 | W11: 공제금액(원) | Y11: 임금항목 | AA11: 지급금액(원) | AC11: 공제 항목 | AE11: 공제금액(원) | AG11: 임금항목 | AI11: 지급금액(원) | AK11: 공제 항목 | AM11: 공제금액(원) | AO11: 임금항목 | AQ11: 지급금액(원) | AS11: 공제 항목 | AU11: 공제금액(원) | AW11: 임금항목 | AY11: 지급금액(원) | BA11: 공제 항목 | BC11: 공제금액(원)
A12: 매월 지급 | B12: 기본급 | C12: =VLOOKUP(A1,급여대장!$A$6:$AD$13,7,0) | E12: 건강보험 | G12: =VLOOKUP(A1,급여대장!$A$6:$AD$13,16,0) -> 0 | I12: 매월 지급 | J12: 기본급 | K12: =VLOOKUP(I1,급여대장!$A$6:$AD$15,7,0) | M12: 건강보험 | O12: =VLOOKUP($I$1,급여대장!$A$6:$AD$15,16,0) -> 0 | Q12: 매월 지급 | R12: 기본급 | S12: =VLOOKUP($Q$1,급여대장!$A$6:$AD$15,7,0) | U12: 건강보험 | W12: =VLOOKUP($Q$1,급여대장!$A$6:$AD$15,16,0) -> 0 | Y12: 매월 지급 | Z12: 기본급 | AA12: =VLOOKUP($Y$1,급여대장!$A$6:$AD$15,7,0) -> #N/A | AC12: 건강보험 | AE12: =VLOOKUP($Y$1,급여대장!$A$6:$AD$15,16,0) -> #N/A | AG12: 매월 지급 | AH12: 기본급 | AI12: =VLOOKUP(AG1,급여대장!$A$6:$AD$15,7,0) -> #N/A | AK12: 건강보험 | AM12: =VLOOKUP($AG$1,급여대장!$A$6:$AD$15,16,0) -> #N/A | AO12: 매월 지급 | AP12: 기본급 | AQ12: =VLOOKUP(AO1,급여대장!$A$6:$AD$15,7,0) -> #N/A | AS12: 건강보험 | AU12: =VLOOKUP(AO1,급여대장!$A$6:$AD$15,16,0) -> #N/A | AW12: 매월 지급 | AX12: 기본급 | AY12: =VLOOKUP(AW1,급여대장!$A$6:$AD$15,7,0) -> #N/A | BA12: 건강보험 | BC12: =VLOOKUP(AW1,급여대장!$A$6:$AD$15,16,0) -> #N/A
B13: 식대 | C13: =VLOOKUP(A1,급여대장!$A$6:$AD$13,8,0) -> 0 | E13: 요양보험 | G13: =VLOOKUP(A1,급여대장!$A$6:$AD$13,17,0) -> 0 | J13: 식대 | K13: =VLOOKUP(I1,급여대장!$A$6:$AD$15,8,0) -> 0 | M13: 요양보험 | O13: =VLOOKUP($I$1,급여대장!$A$6:$AD$15,17,0) -> 0 | R13: 식대 | S13: =VLOOKUP($Q$1,급여대장!$A$6:$AD$15,8,0) -> 0 | U13: 요양보험 | W13: =VLOOKUP($Q$1,급여대장!$A$6:$AD$15,17,0) -> 0 | Z13: 식대 | AA13: =VLOOKUP($Y$1,급여대장!$A$6:$AD$15,8,0) -> #N/A | AC13: 요양보험 | AE13: =VLOOKUP($Y$1,급여대장!$A$6:$AD$15,17,0) -> #N/A | AH13: 식대 | AI13: =VLOOKUP($AG$1,급여대장!$A$6:$AD$15,8,0) -> #N/A | AK13: 요양보험 | AM13: =VLOOKUP($AG$1,급여대장!$A$6:$AD$15,17,0) -> #N/A | AP13: 식대 | AQ13: =VLOOKUP(AO1,급여대장!$A$6:$AD$15,8,0) -> #N/A | AS13: 요양보험 | AU13: =VLOOKUP(AO1,급여대장!$A$6:$AD$15,17,0) -> #N/A | AX13: 식대 | AY13: =VLOOKUP(AW1,급여대장!$A$6:$AD$15,8,0) -> #N/A | BA13: 요양보험 | BC13: =VLOOKUP(AW1,급여대장!$A$6:$AD$15,17,0) -> #N/A
B14: 차량유지비 | C14: =VLOOKUP(A1,급여대장!$A$6:$AD$13,9,0) -> 0 | E14: 국민연금 | G14: =VLOOKUP(A1,급여대장!$A$6:$AD$13,18,0) -> 0 | J14: 차량유지비 | K14: =VLOOKUP($I$1,급여대장!$A$6:$AD$15,9,0) -> 0 | M14: 국민연금 | O14: =VLOOKUP($I$1,급여대장!$A$6:$AD$15,18,0) -> 0 | R14: 차량유지비 | S14: =VLOOKUP($Q$1,급여대장!$A$6:$AD$15,9,0) -> 0 | U14: 국민연금 | W14: =VLOOKUP($Q$1,급여대장!$A$6:$AD$15,18,0) -> 0 | Z14: 차량유지비 | AA14: =VLOOKUP($Y$1,급여대장!$A$6:$AD$15,9,0) -> #N/A | AC14: 국민연금 | AE14: =VLOOKUP($Y$1,급여대장!$A$6:$AD$15,18,0) -> #N/A | AH14: 차량유지비 | AI14: =VLOOKUP($AG$1,급여대장!$A$6:$AD$15,9,0) -> #N/A | AK14: 국민연금 | AM14: =VLOOKUP($AG$1,급여대장!$A$6:$AD$15,18,0) -> #N/A | AP14: 차량유지비 | AQ14: =VLOOKUP(AO1,급여대장!$A$6:$AD$15,9,0) -> #N/A | AS14: 국민연금 | AU14: =VLOOKUP(AO1,급여대장!$A$6:$AD$15,18,0) -> #N/A | AX14: 차량유지비 | AY14: =VLOOKUP(AW1,급여대장!$A$6:$AD$15,9,0) -> #N/A | BA14: 국민연금 | BC14: =VLOOKUP(AW1,급여대장!$A$6:$AD$15,18,0) -> #N/A
B15: 연장수당 | C15: =VLOOKUP(A1,급여대장!$A$6:$AD$13,10,0) | E15: 고용보험 | G15: =VLOOKUP(A1,급여대장!$A$6:$AD$13,19,0) -> 0 | J15: 연장수당 | K15: =VLOOKUP($I$1,급여대장!$A$6:$AD$15,10,0) | M15: 고용보험 | O15: =VLOOKUP($I$1,급여대장!$A$6:$AD$15,19,0) -> 0 | R15: 연장수당 | S15: =VLOOKUP($Q$1,급여대장!$A$6:$AD$15,10,0) | U15: 고용보험 | W15: =VLOOKUP($Q$1,급여대장!$A$6:$AD$15,19,0) -> 0 | Z15: 연장수당 | AA15: =VLOOKUP($Y$1,급여대장!$A$6:$AD$15,10,0) -> #N/A | AC15: 고용보험 | AE15: =VLOOKUP($Y$1,급여대장!$A$6:$AD$15,19,0) -> #N/A | AH15: 연장수당 | AI15: =VLOOKUP($AG$1,급여대장!$A$6:$AD$15,10,0) -> #N/A | AK15: 고용보험 | AM15: =VLOOKUP($AG$1,급여대장!$A$6:$AD$15,19,0) -> #N/A | AP15: 연장근로수당 | AQ15: =VLOOKUP(AO1,급여대장!$A$6:$AD$15,10,0) -> #N/A | AS15: 고용보험 | AU15: =VLOOKUP(AO1,급여대장!$A$6:$AD$15,19,0) -> #N/A | AX15: 연장근로수당 | AY15: =VLOOKUP(AW1,급여대장!$A$6:$AD$15,10,0) -> #N/A | BA15: 고용보험 | BC15: =VLOOKUP(AW1,급여대장!$A$6:$AD$15,19,0) -> #N/A
B16: 휴일근로수당 | C16: =VLOOKUP(A1,급여대장!$A$6:$AD$13,11,0) | E16: 소득세 | G16: =VLOOKUP(A1,급여대장!$A$6:$AD$13,20,0) -> 0 | J16: 휴일근로수당 | K16: =VLOOKUP($I$1,급여대장!$A$6:$AD$15,11,0) | M16: 소득세 | O16: =VLOOKUP($I$1,급여대장!$A$6:$AD$15,20,0) -> 0 | R16: 휴일근로수당 | S16: =VLOOKUP($Q$1,급여대장!$A$6:$AD$15,11,0) | U16: 소득세 | W16: =VLOOKUP($Q$1,급여대장!$A$6:$AD$15,20,0) -> 0 | Z16: 휴일근로수당 | AA16: =VLOOKUP($Y$1,급여대장!$A$6:$AD$15,11,0) -> #N/A | AC16: 소득세 | AE16: =VLOOKUP($Y$1,급여대장!$A$6:$AD$15,20,0) -> #N/A | AH16: 휴일근로수당 | AI16: =VLOOKUP($AG$1,급여대장!$A$6:$AD$15,11,0) -> #N/A | AK16: 소득세 | AM16: =VLOOKUP($AG$1,급여대장!$A$6:$AD$15,20,0) -> #N/A | AP16: 연차수당 | AQ16: =VLOOKUP(AO1,급여대장!$A$6:$AD$15,11,0) -> #N/A | AS16: 소득세 | AU16: =VLOOKUP(AO1,급여대장!$A$6:$AD$15,20,0) -> #N/A | AX16: 연차수당 | AY16: =VLOOKUP(AW1,급여대장!$A$6:$AD$15,11,0) -> #N/A | BA16: 소득세 | BC16: =VLOOKUP(AW1,급여대장!$A$6:$AD$15,20,0) -> #N/A
B17: 연차수당 | C17: =VLOOKUP(A1,급여대장!$A$6:$AD$15,12,0) -> 0 | E17: 주민세 | G17: =VLOOKUP(A1,급여대장!$A$6:$AD$13,21,0) -> 0 | J17: 연차수당 | K17: =VLOOKUP(I1,급여대장!$A$6:$AD$15,12,0) -> 0 | M17: 주민세 | O17: =VLOOKUP($I$1,급여대장!$A$6:$AD$15,21,0) -> 0 | R17: 연차수당 | S17: =VLOOKUP(Q1,급여대장!$A$6:$AD$15,12,0) -> 0 | U17: 주민세 | W17: =VLOOKUP($Q$1,급여대장!$A$6:$AD$15,21,0) -> 0 | Z17: 연차수당 | AA17: =VLOOKUP(Y1,급여대장!$A$6:$AD$15,12,0) -> #N/A | AC17: 주민세 | AE17: =VLOOKUP($Y$1,급여대장!$A$6:$AD$15,21,0) -> #N/A | AH17: 연차수당 | AI17: =VLOOKUP(AG1,급여대장!$A$6:$AD$15,12,0) -> #N/A | AK17: 주민세 | AM17: =VLOOKUP($AG$1,급여대장!$A$6:$AD$15,21,0) -> #N/A | AS17: 주민세 | AU17: =VLOOKUP(AO1,급여대장!$A$6:$AD$15,21,0) -> #N/A | BA17: 주민세 | BC17: =VLOOKUP(AW1,급여대장!$A$6:$AD$15,21,0) -> #N/A
A22: 격월 또는부정기 지급 | B22: 상여금 | C22: =VLOOKUP(A1,급여대장!$A$6:$AD$13,13,0) -> 0 | I22: 격월 또는부정기 지급 | J22: 상여금 | K22: =VLOOKUP($I$1,급여대장!$A$6:$AD$15,13,0) -> 0 | Q22: 격월 또는부정기 지급 | R22: 상여금 | S22: =VLOOKUP($Q$1,급여대장!$A$6:$AD$15,13,0) -> 0 | Y22: 격월 또는부정기 지급 | Z22: 상여금 | AA22: =VLOOKUP($Y$1,급여대장!$A$6:$AD$15,13,0) -> #N/A | AG22: 격월 또는부정기 지급 | AH22: 상여금 | AI22: =VLOOKUP($Y$1,급여대장!$A$6:$AD$15,13,0) -> #N/A | AO22: 격월 또는부정기 지급 | AP22: 상여금 | AQ22: =VLOOKUP($Y$1,급여대장!$A$6:$AD$15,13,0) -> #N/A | AW22: 격월 또는부정기 지급 | AX22: 상여금 | AY22: =VLOOKUP($Y$1,급여대장!$A$6:$AD$15,13,0) -> #N/A
AP23: 연차수당 | AQ23: =VLOOKUP(AO1,급여대장!$A$6:$AD$15,12,0) -> #N/A | AX23: 연차수당 | AY23: =VLOOKUP(AW1,급여대장!$A$6:$AD$15,12,0) -> #N/A
A25: 지급액 계 | C25: =SUM(C12:D24) -> 0 | E25: 공제액 계 | G25: =SUM(G12:H24) -> 0 | I25: 지급액 계 | K25: =SUM(K12:L24) -> 0 | M25: 공제액 계 | O25: =SUM(O12:P24) -> 0 | Q25: 지급액 계 | S25: =SUM(S12:T24) -> 0 | U25: 공제액 계 | W25: =SUM(W12:X24) -> 0 | Y25: 지급액 계 | AA25: =SUM(AA12:AB24) -> #N/A | AC25: 공제액 계 | AE25: =SUM(AE12:AF24) -> #N/A | AG25: 지급액 계 | AI25: =SUM(AI12:AJ24) -> #N/A | AK25: 공제액 계 | AM25: =SUM(AM12:AN24) -> #N/A | AO25: 지급액 계 | AQ25: =SUM(AQ12:AR24) -> #N/A | AS25: 공제액 계 | AU25: =SUM(AU12:AV24) -> #N/A | AW25: 지급액 계 | AY25: =SUM(AY12:AZ24) -> #N/A | BA25: 공제액 계 | BC25: =SUM(BC12:BD24) -> #N/A
E26: 실수령액(원) | G26: =C25-G25 -> 0 | M26: 실수령액(원) | O26: =K25-O25 -> 0 | U26: 실수령액(원) | W26: =S25-W25 -> 0 | AC26: 실수령액(원) | AE26: =AA25-AE25 -> #N/A | AK26: 실수령액(원) | AM26: =AI25-AM25 -> #N/A | AS26: 실수령액(원) | AU26: =AQ25-AU25 -> #N/A | BA26: 실수령액(원) | BC26: =AY25-BC25 -> #N/A
A27: 계 산 방 법 | I27: 계 산 방 법 | Q27: 계 산 방 법 | Y27: 계 산 방 법 | AG27: 계 산 방 법 | AO27: 계 산 방 법 | AW27: 계 산 방 법
A28: 구분 | C28: 산출식 또는 산출방법 | G28: 지급액(원) | I28: 구분 | K28: 산출식 또는 산출방법 | O28: 지급액(원) | Q28: 구분 | S28: 산출식 또는 산출방법 | W28: 지급액(원) | Y28: 구분 | AA28: 산출식 또는 산출방법 | AE28: 지급액(원) | AG28: 구분 | AI28: 산출식 또는 산출방법 | AM28: 지급액(원) | AO28: 구분 | AQ28: 산출식 또는 산출방법 | AU28: 지급액(원) | AW28: 구분 | AY28: 산출식 또는 산출방법 | BC28: 지급액(원)
A29: 기본급 | C29: 통상시급x209시간-(식대-차량유지비) | G29: =C12 | I29: 기본급 | K29: 통상시급x209시간-(식대-차량유지비) | O29: =K12 | Q29: 기본급 | S29: 통상시급x209시간-(식대-차량유지비) | W29: =S12 | Y29: 기본급 | AA29: 통상시급x209시간-(식대-차량유지비) | AE29: =AA12 -> #N/A | AG29: 기본급 | AI29: 통상시급x209시간-(식대-차량유지비) | AM29: =AI12 -> #N/A | AO29: 기본급 | AQ29: 통상시급x209시간-(식대-차량유지비) | AU29: =AQ12 -> #N/A | AW29: 기본급 | AY29: 통상시급x209시간-(식대-차량유지비) | BC29: =AY12 -> #N/A
A30: 연장수당 | C30: 통상시급x | E30: =VLOOKUP(A1,급여대장!$A$6:$O$15,6,0) | F30: 시간 | G30: =C15 | I30: 연장수당 | K30: 통상시급x | M30: =VLOOKUP(I1,급여대장!$A$6:$O$15,6,0) | N30: 시간 | O30: =K15 | Q30: 연장수당 | S30: 통상시급x | U30: =VLOOKUP(Q1,급여대장!$A$6:$O$15,6,0) | V30: 시간 | W30: =S15 | Y30: 연장수당 | AA30: 통상시급x | AC30: =VLOOKUP(Y1,급여대장!$A$6:$O$15,6,0) -> #N/A | AD30: 시간 | AE30: =AA15 -> #N/A | AG30: 연장수당 | AI30: 통상시급x | AK30: =VLOOKUP(AG1,급여대장!$A$6:$O$15,6,0) -> #N/A | AL30: 시간 | AM30: =AI15 -> #N/A | AO30: 연장근로수당 | AQ30: 통상시급 x 연장근로시간x1..5 | AU30: =AQ15 -> #N/A | AW30: 연장근로수당 | AY30: 통상시급 x 연장근로시간x1..5 | BC30: =AY15 -> #N/A
A31: 휴일근로수당 | C31: 통상시급x | E31: =VLOOKUP(A1,'포괄 급여계산'!$A$3:$S$12,18,0) | F31: 시간 | G31: =C16 | I31: 휴일근로수당 | K31: 통상시급x | M31: =VLOOKUP(I1,'포괄 급여계산'!$A$3:$S$12,18,0) | N31: 시간 | O31: =K16 | Q31: 휴일근로수당 | S31: 통상시급x | U31: =VLOOKUP(Q1,'포괄 급여계산'!$A$3:$S$12,18,0) | V31: 시간 | W31: =S16 | Y31: 휴일근로수당 | AA31: 통상시급x | AC31: =VLOOKUP(Y1,'포괄 급여계산'!$A$3:$S$12,18,0) -> #N/A | AD31: 시간 | AE31: =AA16 -> #N/A | AG31: 휴일근로수당 | AI31: 통상시급x | AK31: =VLOOKUP(AG1,'포괄 급여계산'!$A$3:$S$12,18,0) -> #N/A | AL31: 시간 | AM31: =AI16 -> #N/A
A32: 연 차 수 당 | C32: 통상시급x | E32: =VLOOKUP(A1,'포괄 급여계산'!$A$3:$AG$19,26,0) | F32: 시간 | G32: =C17 -> 0 | I32: 연 차 수 당 | K32: 통상시급x | M32: =VLOOKUP(I1,'포괄 급여계산'!$A$3:$AG$19,26,0) | N32: 시간 | O32: =K17 -> 0 | Q32: 연 차 수 당 | S32: 통상시급x | U32: =VLOOKUP(Q1,'포괄 급여계산'!$A$3:$AG$19,26,0) | V32: 시간 | W32: =S17 -> 0 | Y32: 연 차 수 당 | AA32: 통상시급x | AC32: =VLOOKUP(Y1,'포괄 급여계산'!$A$3:$AG$19,26,0) -> #N/A | AD32: 시간 | AE32: =AA17 -> #N/A | AG32: 연 차 수 당 | AI32: 통상시급x | AK32: =VLOOKUP(AG1,'포괄 급여계산'!$A$3:$AG$19,26,0) -> #N/A | AL32: 시간 | AM32: =AI17 -> #N/A
A33: 귀하에 노고에 감사드립니다. | I33: 귀하에 노고에 감사드립니다. | Q33: 귀하에 노고에 감사드립니다. | Y33: 귀하에 노고에 감사드립니다. | AG33: 귀하에 노고에 감사드립니다. | AO33: (공지) 회사 내 급여공유는 해고 사유에 해당합니다. 개인 급여명세서 관리에 각별히 주의 부탁드립니다. | AW33: (공지) 회사 내 급여공유는 해고 사유에 해당합니다. 개인 급여명세서 관리에 각별히 주의 부탁드립니다.

Sheet 임금명세서 (15~18)
A1: 15 | I1: =A1+1 -> 16 | Q1: =I1+1 -> 17 | Y1: =Q1+1 -> 18 | AG1: =Y1+1 -> 19 | AO1: =AG1+1 -> 20 | AW1: =AO1+1 -> 21
A3: 임 금 명 세 서 | I3: 임 금 명 세 서 | Q3: 임 금 명 세 서 | Y3: 임 금 명 세 서 | AG3: 임 금 명 세 서 | AO3: 임 금 명 세 서 | AW3: 임 금 명 세 서
A5: 회사명 | C5: =급여대장!$A$4 -> 제이엠건축인테리어 주식회사 | I5: 회사명 | K5: =급여대장!$A$4 -> 제이엠건축인테리어 주식회사 | Q5: 회사명 | S5: =급여대장!$A$4 -> 제이엠건축인테리어 주식회사 | Y5: 회사명 | AA5: =급여대장!$A$4 -> 제이엠건축인테리어 주식회사 | AG5: 회사명 | AI5: =급여대장!$A$4 -> 제이엠건축인테리어 주식회사 | AO5: 회사명 | AQ5: =급여대장!$A$4 -> 제이엠건축인테리어 주식회사 | AW5: 회사명 | AY5: =급여대장!$A$4 -> 제이엠건축인테리어 주식회사
A6: 급여귀속 | C6: =급여대장!$AD$3 -> 46082 | E6: 지급일 | G6: =급여대장!$AD$4 -> 매월 5일 | I6: 급여귀속 | K6: =급여대장!$AD$3 -> 46082 | M6: 지급일 | O6: =급여대장!$AD$4 -> 매월 5일 | Q6: 급여귀속 | S6: =급여대장!$AD$3 -> 46082 | U6: 지급일 | W6: =급여대장!$AD$4 -> 매월 5일 | Y6: 급여귀속 | AA6: =급여대장!$AD$3 -> 46082 | AC6: 지급일 | AE6: =급여대장!$AD$4 -> 매월 5일 | AG6: 급여귀속 | AI6: =급여대장!$AD$3 -> 46082 | AK6: 지급일 | AM6: =급여대장!$AD$4 -> 매월 5일 | AO6: 급여귀속 | AQ6: =급여대장!$AD$3 -> 46082 | AS6: 지급일 | AU6: =급여대장!$AD$4 -> 매월 5일 | AW6: 급여귀속 | AY6: =급여대장!$AD$3 -> 46082 | BA6: 지급일 | BC6: =급여대장!$AD$4 -> 매월 5일
A7: 성명 | C7: =급여대장!#REF! -> #REF! | E7: 생년월일 | G7: =급여대장!#REF! -> #REF! | I7: 성명 | K7: =VLOOKUP(I1,급여대장!$A$6:$B$15,2,0) -> #N/A | M7: 생년월일 | O7: =급여대장!#REF! -> #REF! | Q7: 성명 | S7: =VLOOKUP(Q1,급여대장!$A$6:$B$15,2,0) -> #N/A | U7: 생년월일 | W7: =급여대장!#REF! -> #REF! | Y7: 성명 | AA7: =VLOOKUP(Y1,급여대장!$A$6:$B$15,2,0) -> #N/A | AC7: 생년월일 | AE7: =급여대장!#REF! -> #REF! | AG7: 성명 | AI7: =VLOOKUP(AG1,급여대장!$A$6:$B$15,2,0) -> #N/A | AK7: 생년월일 | AM7: =VLOOKUP(AG1,급여대장!$A$6:$AD$15,3,0) -> #N/A | AO7: 성명 | AQ7: =VLOOKUP(AO1,급여대장!$A$6:$B$15,2,0) -> #N/A | AS7: 생년월일 | AU7: =VLOOKUP(AO1,급여대장!$A$6:$AD$15,3,0) -> #N/A | AW7: 성명 | AY7: =VLOOKUP(AW1,급여대장!$A$6:$B$15,2,0) -> #N/A | BA7: 생년월일 | BC7: =VLOOKUP(AW1,급여대장!$A$6:$AD$15,3,0) -> #N/A
A8: 세부 내역
I9: 세부 내역 | Q9: 세부 내역 | Y9: 세부 내역 | AG9: 세부 내역 | AO9: 세부 내역 | AW9: 세부 내역
A10: 지 급 | E10: 공 제 | I10: 지 급 | M10: 공 제 | Q10: 지 급 | U10: 공 제 | Y10: 지 급 | AC10: 공 제 | AG10: 지 급 | AK10: 공 제 | AO10: 지 급 | AS10: 공 제 | AW10: 지 급 | BA10: 공 제
A11: 임금항목 | C11: 지급금액(원) | E11: 공제 항목 | G11: 공제금액(원) | I11: 임금항목 | K11: 지급금액(원) | M11: 공제 항목 | O11: 공제금액(원) | Q11: 임금항목 | S11: 지급금액(원) | U11: 공제 항목 | W11: 공제금액(원) | Y11: 임금항목 | AA11: 지급금액(원) | AC11: 공제 항목 | AE11: 공제금액(원) | AG11: 임금 항목 | AI11: 지급 금액(원) | AK11: 공제 항목 | AM11: 공제 금액(원) | AO11: 임금 항목 | AQ11: 지급 금액(원) | AS11: 공제 항목 | AU11: 공제 금액(원) | AW11: 임금 항목 | AY11: 지급 금액(원) | BA11: 공제 항목 | BC11: 공제 금액(원)
