Workbook

Sheet 법인 2026
A2: 본 공사 금액 | B2: =SUM(표1_4[본 공사 금액]) -> 154518000
A3: 추가 공사 금액 | B3: =SUM(표1_4[추가 공사 금액]) -> 2816000
A4: 합계 | B4: =SUM(B2:B3) -> 157334000
A5: 순이익 금액 | B5: =SUM(M8:M80) -> 84148821 | C5: =B5/B4 -> 0.53484193
A6: 고용산재보험 | B6: =SUM(표1_4[고용산재금액]) -> 1614998
A7: 현장명 | B7: 계약일 | C7: 시작일 | D7: 준공일 | E7: 공사명 | F7: 발주자 명 | G7: 대표자 명 | H7: 구분 | I7: 법인등록번호 | J7: 사업자등록증(주민등록증) | K7: 본 공사 금액 | L7: 추가 공사 금액 | M7: 순이익 금액 | N7: % | O7: 현장 주소 | P7: 공사유형 | Q7: 도급 종류 | R7: 전화번호 | S7: 비고1 | T7: 고용산재금액
A8: 대상힐스 미용실 | B8: 46024 | C8: 46025 | D8: 46046 | E8: 대상힐스미용실 인테리어 | F8: 이정현 | G8: 이정현 | H8: 개인 | K8: 30800000 | M8: 13308492 | N8: 0.48 | O8: 경남 창원시 성산구 내동 산 33-1 대상 힐스에비뉴 창원 더 퍼스트상가 128동 110호 | P8: 유지보수 | Q8: 원도급 | R8: 010-8617-6919 | T8: 481403
A9: 무동 토킹영어학원 | B9: 계약서x | C9: 계약서x | D9: 계약서x | E9: 무동 토킹영어학원 인테리어 | K9: 4862000 | M9: 2371297 | N9: 0.54 | T9: 100083
A10: 부산대 원예학과 | B10: 46038 | C10: 46038 | D10: 46051 | E10: 2025 PNU 펜토미노 융합전공 원예생명과학과 환경개선 공사 | F10: 부산대학교 | G10: 최재원 | H10: 유지보수 | I10: 원도급 | J10: 055-350-5174 | K10: 24000000 | M10: 11972528 | N10: 0.55 | O10: 경남 밀양시 삼랑진읍 삼랑진로 1268-50 부산대학교 밀양캠퍼스 생명자원과학관 4층 복도(3451호 앞) | P10: 유지보수 | Q10: 원도급 | R10: 055-350-5174 | T10: 217532
A11: 서경방송 1,8층 디자인 | B11: 46008 | C11: 46008 | D11: 46038 | E11: ㈜서경방송 1,8층 도면작업 | F11: 서경방송 | K11: 5830000
A12: 부산대 바이오소재 작년 잔금 | B12: 승락서 | C12: 승락서 | D12: 승락서 | K12: 8000000 | O12: 경남 밀양시 삼랑진읍 삼랑진로 1268-50 부산대학교 밀양캠퍼스 바이오소재학과 | P12: 유지보수 | Q12: 원도급 | R12: 055-350-5174
A13: 주남 앨리브 | O13: 경상남도 창원시 의창구 동읍 주남로 71번길 3 | P13: 유지보수 | Q13: 원도급 | R13: 010-3067-0007 | S13: 26년도 실적신고
A14: 어반브릭스 기타학원 | B14: 46057 | C14: 46058 | D14: 46065 | E14: 기타학원 인테리어 | F14: 최지원 | G14: 최지원 | H14: 개인 | J14: 881105-1 | K14: 11836000 | M14: =[1]내역서!$Q$4 -> 5919811 | N14: =[1]내역서!$R$4 -> 0.55016831 | O14: 경남 창원시 의창구 의창대로 835 | P14: 유지보수 | Q14: 원도급 | R14: 010-2592-0813 | T14: 177460
A15: 제이디윙스 6층 | B15: 46072 | C15: 46072 | D15: 46084 | E15: 영어학원인테리어 | F15: 박은혜 | G15: 박은혜 | K15: 10857000 | L15: 2816000 | M15: =[2]내역서!$Q$4 -> 5218661 | N15: =[2]내역서!$R$4 -> 0.41984401 | T15: 251807
A16: 감계아파트 202동 605호 | K16: 12000000 | M16: =[3]내역서!$Q$4 -> 5860348 | N16: =[3]내역서!$R$4 -> 0.48273048
A17: 감계아파트 203동 1305호 | O17: 경상남도 창원시 마산합포구 현동7길 18,1층 | P17: 유지보수 | Q17: 원도급
A18: RISE 기능성푸드평가 동물조직분석실 교육 환경 개선 공사 | B18: 46072 | C18: 46072 | D18: 46078 | E18: RISE 기능성푸드평가 동물조직분석실 교육 환경 개선 공사 | F18: 부산대학교 | G18: 최재원 | H18: 유지보수 | I18: 원도급 | J18: 055-350-5174 | K18: 10000000 | M18: =[4]내역서!$Q$4 -> 4471732 | N18: =[4]내역서!$R$4 -> 0.49085971 | O18: 경남 밀양시 삼랑진읍 삼랑진로 1268-50 부산대학교 밀양캠퍼스 바이오소재학과 | P18: 유지보수 | Q18: 원도급 | R18: 055-350-5174 | T18: 113793
A19: 현대마린엔진 대표실 | B19: 46084 | C19: 46084 | D19: 46086 | E19: HD현대마린엔진 대표이사실 개선 공사 | F19: 강영 | G19: 강영 | J19: 609-81-48213 | K19: 10593000 | M19: =[5]내역서!$Q$4 -> 6181116 | N19: =[4]내역서!$R$4 -> 0.49085971 | O19: 경남 창원시 성산구 적현로 222
A20: 장유사무실 | B20: 46084 | C20: 46084 | D20: 46102 | E20: 주식회사 대한재해예방 인테리어 | F20: 주식회사 대한재해예방 | G20: 김종호 | I20: 195511-0277404 | J20: 565-86-02533 | K20: 24090000 | M20: =[6]내역서!$Q$4 -> 21733030 | N20: =[6]내역서!$R$4 -> 0.90215982 | O20: 경남 김해시 대청동 번화1로 40, 파로스타워 206호 | Q20: 원도급 | T20: 220365
A21: 지엔티 회의테이블구매 | K21: 407000 | M21: 77000
A22: 지엔티 책상구매 | K22: 143000 | M22: 22000
A23: 경남 테크노파크 | M23: =[7]내역서!$Q$4 -> 3506403 | N23: =[7]내역서!$R$4 -> 0.90371211 | T23: 52555
A24: 가로수길 촌놈스시(디자인) | B24: 46077 | E24: 가로수길 촌놈스시 | F24: 정맹근 | G24: 정맹근 | K24: 1100000 | M24: =[7]내역서!$Q$4 -> 3506403 | N24: =[7]내역서!$R$4 -> 0.90371211

Sheet 법인 2025
A2: 본 공사 금액 | B2: =SUM(표1[본 공사 금액]) -> 2162445566
A3: 추가 공사 금액 | B3: =SUM(표1[추가 공사 금액]) -> 162796000
A4: 합계 | B4: =SUM(B2:B3) -> 2325241566
A5: 순이익 금액 | B5: =SUM(표1[순이익 금액]) -> 655064499
A6: 고용산재보험 | B6: =SUM(표1[고용산재보험]) -> 26358565
A7: 현장명 | B7: 계약일 | C7: 시작일 | D7: 준공일 | E7: 공사명 | F7: 발주자 명 | G7: 대표자 명 | H7: 구분 | I7: 법인등록번호 | J7: 사업자등록증(주민등록증) | K7: 본 공사 금액 | L7: 추가 공사 금액 | M7: 순이익 금액 | N7: % | O7: 현장 주소 | P7: 공사유형 | Q7: 도급 종류 | R7: 전화번호 | S7: 비고1 | T7: 고용산재보험
A8: 터보링크 | B8: 46017 | C8: 45660 | D8: 45666 | E8: 계단실 인테리어 | F8: 터보링크 | G8: 하현천 | H8: 법인사업자 | I8: 194211-0046286 | J8: 609-81-46495 | K8: 33220000 | M8: 10654726 | N8: 0.35
A9: 사파동 변호사 사무실 | B9: 46018 | C9: 46022 | D9: 45670 | E9: 사파동 변호사 사무실 | F9: 이홍열법률사무소 | G9: 이홍열 | H9: 개인사업자 | J9: 311-21-02295 | K9: 27335000 | M9: 12086038 | N9: 0.49 | O9: 경남 창원시 마산회원구 315대로 지하 758.l열6-2호 | P9: 유지보수 | Q9: 원도급 | R9: 010-8600-4162
A10: 합성동네일샵 | B10: 45659 | C10: 45659 | D10: 45694 | E10: 더 젤 네일샵 인테리어 | F10: 더 젤 | G10: 김지현 | H10: 개인사업자 | I10: x | J10: 804-68-00270 | K10: 32500000 | M10: 12373728 | N10: 0.42 | O10: 경남 창원시 마산회원구 315대로 지하 758.l열6-2호 | P10: 유지보수 | Q10: 원도급 | R10: 010-8600-4162
A11: 양산타코야끼 인테리어 | B11: 45684 | C11: 45692 | D11: 45711 | E11: 양산타코야끼 인테리어 | F11: 오찬우 | G11: 오찬우 | H11: 개인 | I11: x | J11: 951121-1 | K11: 29469000 | L11: 3949000 | M11: 11767783 | N11: 0.39 | O11: 경남 양산시 물금읍 물금로 가촌리 1275-7 102호 | P11: 유지보수 | Q11: 원도급 | R11: 010-8528-9107 | S11: 추가 공사 계약서o | T11: 499665
A12: 서상동사무실 | B12: 45678 | C12: 45678 | D12: 45708 | E12: 라온메디칼 사무실 인테리어 | F12: 비코 부경 | G12: 양진열 | H12: 개인사업자 | I12: x | J12: 279-25-00860 | K12: 33000000 | M12: 10298373 | N12: 0.34 | O12: 경상남도 창원시 의창구 서상동 666-6,502호 | P12: 유지보수 | Q12: 원도급 | R12: 055-241-1123 | T12: 496613
A13: MH에탄올 사무실 인테리어 | B13: 45688 | C13: 45688 | D13: 45716 | E13: MH에탄올 사무실 인테리어 | F13: MH에탄올 | G13: 최동호 | H13: 법인사업자 | I13: 190111-0003563 | J13: 608-81-03800 | K13: 88902000 | L13: 2134000 | M13: 28792182 | N13: 0.34 | O13: 경남 창원시 마산회원구 내서읍 광려천남로 25,1층 | P13: 유지보수 | Q13: 원도급 | R13: 055-231-0701 | S13: 추가 공사 계약서x 250320 | T13: 2101478
A14: 지엔티 가구 | B14: 계약서x | C14: 계약서x | D14: 계약서x | E14: 지엔티 가구 | F14: 지엔티 | H14: 법인사업자 | K14: 814000 | M14: 154000 | N14: 0.21
A15: HD프랭크샤프트 가구 | B15: 계약서x | C15: 계약서x | D15: 계약서x | E15: HD프랭크샤프트 가구 | F15: 여인표 | H15: 법인사업자 | K15: 8019000 | M15: 1480000 | N15: 0.2 | S15: 견적서o
A16: 웨딩홀 도면작업 | B16: 계약서x | C16: 계약서x | D16: 계약서x | E16: 인테리어 도면 | F16: 보다(PLUS) | K16: 3300000 | M16: 1200000 | N16: 0.55
A17: MH에탄올 본관 2,3층 사무실 | B17: 45721 | C17: 45721 | D17: 45763 | E17: ㈜MH에탄올 사무실 인테리어 | F17: ㈜MH에탄올 | G17: 최동호 | H17: 법인사업자 | I17: 190111-0003563 | J17: 608-81-03800 | K17: 160413000 | L17: 8536000 | M17: 55935688 | N17: 0.36 | O17: 경남 창원시 마산회원구 내서읍 광려천남로 25,1층 | P17: 유지보수 | Q17: 원도급 | R17: 055-231-0701 | T17: 2669857
A18: 구산면 카페 건축 | B18: 45723 | C18: 45733 | D18: 45822 | E18: 다구리 109번지 근린생활시설 신축공사 | F18: 민지현 | G18: 민지현 | H18: 개인 | I18: x | J18: 780901-2824441 | K18: 275000000 | L18: 12617000 | M18: 17380423 | N18: 0.1 | O18: 경남 창원시 마산합포구 진동면 다구리 109번지 | P18: 신설 | Q18: 원도급 | R18: 010-9193-7870
A19: 구산면 카페 철거 | B19: 계약서x | C19: 계약서x | D19: 계약서x | K19: 3300000 | M19: 3300000 | N19: 1 | S19: 철거 빽마진
A20: 키움에셋플래너 | B20: 45736 | C20: 45737 | D20: 45750 | E20: 창원 키움에셋플레너 인테리어 | F20: 키움에셋플레너 주식회사 | G20: 조용학 | H20: 법인사업자 | I20: 110111-2776445 | J20: 211-87-33738 | K20: 40000000 | M20: 10606044 | N20: 0.29 | O20: 경남 창원시 의창구 팔용로 428,605(드림피아상가) | P20: 유지보수 | Q20: 원도급 | R20: 010-7723-5954 | T20: 370906
A21: 보루 | B21: 45744 | C21: 45747 | D21: 45747 | E21: 보루(어반브릭스)인테리어 | F21: 보루 창원의창점 | G21: 이건중 | H21: 개인사업자 | I21: x | J21: 521-48-00794 | K21: 2530000 | M21: 830000 | N21: 0.36 | O21: 경상남도 창원시 의창구 중동중앙로 47,1층 1008호 | R21: 010-6410-3837 | S21: 부분 인테리어 | T21: 21936
A22: 미테리어 | B22: 계약서x | C22: 계약서x | D22: 계약서x | E22: 인테리어 도면 | K22: 660000 | M22: 236363 | N22: 0.44
A23: 밀양 네일샵 | B23: 45751 | C23: 45752 | D23: 45775 | E23: 네일샵 인테리어 | F23: 박소연 | G23: 박소연 | H23: 개인사업자 | K23: 16379000 | L23: 4510000 | M23: 9722496 | N23: 0.51 | O23: 경남 밀양시 내이동 770-2,1층 | P23: 유지보수 | Q23: 원도급 | R23: 0106238-4532 | T23: 284145
A24: 현동 네일샵 | B24: 45756 | C24: 45757 | D24: 45777 | E24: 네일샵 인테리어 | F24: 네일유니비 | G24: 조선윤 | H24: 개인사업자 | I24: x | J24: 394-50-01011 | K24: 21000000 | L24: 150000 | M24: 8047766 | N24: 0.42 | O24: 경남 창원시 마산합포구 현동 7길 22,1층 114호 | P24: 유지보수 | Q24: 원도급 | R24: 010-9684-8587 | T24: 339341
A25: 함안 네일샵 | B25: 45760 | C25: 45762 | D25: 45777 | E25: 숲칼프(두피탈모관리샵)인테리어 | F25: 숲칼프 함안점 | G25: 조현영 | H25: 개인사업자 | I25: x | J25: 464-11-02682 | K25: 29000000 | M25: 11657866 | N25: 0.44 | O25: 경남 함안군 가야읍 성내북길 10,102호 | P25: 유지보수 | Q25: 원도급 | R25: 010-3501-2715 | T25: 372250
A26: 용호동(정우상가)뷰티샵 | B26: 45757 | C26: 45762 | D26: 45787 | E26: 셀포렙 라헨느 인테리어 | F26: 박미정 | H26: 개인사업자 | I26: x | J26: 686-37-01449 | K26: 39800000 | M26: 10893394 | N26: 0.3 | O26: 경남 창원시 성산구 원이대로 587,2층 4호 | P26: 유지보수 | Q26: 원도급 | R26: 010-4617-3301 | T26: 505003
A27: 지엔티 가구 | B27: 계약서x | C27: 계약서x | D27: 계약서x | E27: 지엔티 가구 | F27: 지엔티 | H27: 법인사업자 | K27: 396000 | M27: 74000 | N27: 0.21
A28: 지엔티 가구 | B28: 계약서x | C28: 계약서x | D28: 계약서x | E28: 지엔티 가구 | F28: 지엔티 | H28: 법인사업자 | K28: 979000 | M28: 304000 | N28: 0.21
A29: 디자인마산 | B29: 계약서x | C29: 계약서x | D29: 계약서x | E29: 인테리어 도면 | K29: 660000 | M29: 200000 | N29: 0.44
A30: 경남산소 | B30: 45777 | C30: 45742 | D30: 45813 | E30: 경남산소 사무실 리모델링 | F30: 이종석 | G30: 이종석 | K30: 72000000 | L30: 5016000 | M30: 23206242 | N30: 0.34 | P30: 유지보수 | Q30: 원도급 | R30: 010-2978-3493 | T30: 800374
A31: 진례 제일전자공업 | B31: 45792 | C31: 45803 | D31: 45853 | E31: 제일전자공업㈜ 전시실 인테리어 | F31: 제일전자공업㈜ | K31: 52800000 | L31: 6468000 | M31: 18357259 | N31: 0.38 | O31: 경남 김해시 진례면 고모로216번길 59-5 | T31: 737873
A32: 합성동 이자카야 | B32: 45803 | C32: 45803 | D32: 45811 | E32: 마산종말이 | F32: 정민철 | G32: 정민철 | H32: 개인사업자 | J32: 160-12-02394 | K32: 2800000 | L32: 165000 | M32: 1135181 | N32: 0.43
A33: 진해 누룽지삼계탕 | B33: 45818 | C33: 45823 | D33: 45858 | E33: 이우철한방누릉지삼계탕(진해점) | F33: 김성남 | G33: 김성남 | H33: 개인사업자 | J33: 584-71-00662 | K33: 83985000 | L33: 27500000 | M33: 31356294 | N33: 0.31 | O33: 경남 창원시 진해구 천자로 393 | P33: 유지보수 | Q33: 원도급 | R33: 010-3857-0574 | T33: 174581
A34: 상남동 금다방 빙수 | B34: 계약서x | C34: 계약서x | D34: 계약서x | E34: 상남동 금다방 빙수 철거 | K34: 2700000 | M34: 760908 | N34: 0.31
A35: 이홍열법률사무소 | B35: 45831 | C35: 45831 | D35: 45861 | E35: 이홍열법률사무소 인테리어 | F35: 이홍열법률사무소 | G35: 이홍열 | H35: 개인사업자 | J35: 311-21-02295 | K35: 53119000 | L35: 15114000 | M35: 12086038 | N35: 0.26 | O35: 경상남도 창원시 성산구 창이대로 689번길 4-4,301호 | P35: 유지보수 | Q35: 원도급 | R35: 010-2997-2019 | T35: 650181
A36: 구산면 도만 카페 | B36: 45828 | C36: 45830 | D36: 45869 | E36: 도만 카페 인테리어 | F36: 민지현 | G36: 민지현 | H36: 개인 | J36: 780901-2824441 | K36: 178000000 | M36: 60816168 | N36: 0.38 | O36: 경남 창원시 마산합포구 진동면 다구리 109번지 | P36: 유지보수 | Q36: 원도급 | R36: 010-9193-7870 | T36: 4352039
A37: 진주스포츠센터 | B37: 45845 | D37: 45901 | E37: 스포츠가치센터 이용자 휴게공간 및 흡연부스 공사 | F37: 서울올림픽기념국민체육진흥공단 | G37: 최형도 | H37: 공공기간 | K37: 36905000 | M37: 17411938 | N37: 0.53 | O37: 경상남도 진주시 내동면 삼계로 360, 스포츠가치센터 | P37: 유지보수 | Q37: 원도급 | R37: 02-410-1222 | S37: 나라장터 입찰 계약 | T37: 797032
A38: 팔용동 사진관 | B38: 45839 | C38: 45842 | D38: 45852 | E38: 디에프 | F38: 이강우 | G38: 디에프 | H38: 개인사업자 | J38: 418-54-00368 | K38: 7752566 | M38: 3592613 | N38: 0.51 | O38: 경남 창원시 의창구 의창대로 180번길 2,1층 | P38: 유지보수 | Q38: 원도급 | R38: 010-5295-6035 | T38: 145783
A39: 이우철 누수보수작업 | B39: 계약서x | C39: 계약서x | D39: 계약서x | E39: 이우철 누수보수작업 | K39: 2838000 | M39: 2838000 | N39: 1
A40: 디자인마산 | B40: 계약서x | C40: 계약서x | D40: 계약서x | E40: 인테리어 도면 | K40: 990000 | M40: 405000 | N40: 0.45
A41: 주식회사 좋은 | B41: 계약서x | C41: 계약서x | D41: 계약서x | E41: 인테리어 도면 | K41: 440000 | M41: 440000 | N41: 1
...

Sheet 법인 2025 신고내역
A1: 공사명 | B1: 현장명 | C1: 계약일 | D1: 시작일 | E1: 준공일 | F1: 공사명 | G1: 발주자 명 | H1: 대표자 명 | I1: 구분 | J1: 법인등록번호 | K1: 사업자등록증(주민등록증) | L1: 본 공사 금액 | M1: 추가 공사 금액 | N1: 합계 | O1: 순이익 금액 | P1: % | Q1: 현장 주소 | R1: 공사유형 | S1: 도급 종류 | T1: 전화번호 | U1: 비고1 | V1: 분류
A2: 계단실 인테리어 | B2: 터보링크 | C2: 46017 | D2: 45660 | E2: 45666 | F2: 계단실 인테리어 | G2: 터보링크 | H2: 하현천 | I2: 법인사업자 | J2: 194211-0046286 | K2: 609-81-46495 | L2: 33220000 | N2: =SUM(표1_6[[#This Row],[본 공사 금액]:[추가 공사 금액]]) -> 33220000 | O2: 10654726 | P2: 0.35 | V2: 우편
A3: 사파동 변호사 사무실 | B3: 사파동 변호사 사무실 | C3: 46018 | D3: 46022 | E3: 45670 | F3: 사파동 변호사 사무실 | G3: 이홍열법률사무소 | H3: 이홍열 | I3: 개인사업자 | K3: 311-21-02295 | L3: 27335000 | N3: =SUM(표1_6[[#This Row],[본 공사 금액]:[추가 공사 금액]]) -> 27335000 | O3: 12086038 | P3: 0.49 | Q3: 경남 창원시 마산회원구 315대로 지하 758.l열6-2호 | R3: 유지보수 | S3: 원도급 | T3: 010-8600-4162 | V3: 우편
A4: 더 젤 네일샵 인테리어 | B4: 합성동네일샵 | C4: 45659 | D4: 45659 | E4: 45694 | F4: 더 젤 네일샵 인테리어 | G4: 더 젤 | H4: 김지현 | I4: 개인사업자 | J4: x | K4: 804-68-00270 | L4: 32500000 | N4: =SUM(표1_6[[#This Row],[본 공사 금액]:[추가 공사 금액]]) -> 32500000 | O4: 12373728 | P4: 0.42 | Q4: 경남 창원시 마산회원구 315대로 지하 758.l열6-2호 | R4: 유지보수 | S4: 원도급 | T4: 010-8600-4162
A5: 양산타코야끼 인테리어 | B5: 양산타코야끼 인테리어 | C5: 45684 | D5: 45692 | E5: 45711 | F5: 양산타코야끼 인테리어 | G5: 오찬우 | H5: 오찬우 | I5: 개인 | J5: x | K5: 951121-1 | L5: 29469000 | M5: 3949000 | N5: =SUM(표1_6[[#This Row],[본 공사 금액]:[추가 공사 금액]]) -> 33418000 | O5: 11767783 | P5: 0.39 | Q5: 경남 양산시 물금읍 물금로 가촌리 1275-7 102호 | R5: 유지보수 | S5: 원도급 | T5: 010-8528-9107 | U5: 추가 공사 계약서o
A6: 라온메디칼 사무실 인테리어 | B6: 서상동사무실 | C6: 45678 | D6: 45678 | E6: 45708 | F6: 라온메디칼 사무실 인테리어 | G6: 비코 부경 | H6: 양진열 | I6: 개인사업자 | J6: x | K6: 279-25-00860 | L6: 33000000 | N6: =SUM(표1_6[[#This Row],[본 공사 금액]:[추가 공사 금액]]) -> 33000000 | O6: 10298373 | P6: 0.34 | Q6: 경상남도 창원시 의창구 서상동 666-6,502호 | R6: 유지보수 | S6: 원도급 | T6: 055-241-1123
A7: MH에탄올 사무실 인테리어 | B7: MH에탄올 사무실 인테리어 | C7: 45688 | D7: 45688 | E7: 45716 | F7: MH에탄올 사무실 인테리어 | G7: MH에탄올 | H7: 최동호 | I7: 법인사업자 | J7: 190111-0003563 | K7: 608-81-03800 | L7: 88902000 | M7: 2134000 | N7: =SUM(표1_6[[#This Row],[본 공사 금액]:[추가 공사 금액]]) -> 91036000 | O7: 28792182 | P7: 0.34 | Q7: 경남 창원시 마산회원구 내서읍 광려천남로 25,1층 | R7: 유지보수 | S7: 원도급 | T7: 055-231-0701 | U7: 추가 공사 계약서x 250320
A8: 지엔티 가구 | B8: 지엔티 가구 | C8: 계약서x | D8: 계약서x | E8: 계약서x | F8: 지엔티 가구 | G8: 지엔티 | I8: 법인사업자 | L8: 814000 | N8: =SUM(표1_6[[#This Row],[본 공사 금액]:[추가 공사 금액]]) -> 814000 | O8: 154000 | P8: 0.21
A9: HD프랭크샤프트 가구 | B9: HD프랭크샤프트 가구 | C9: 계약서x | D9: 계약서x | E9: 계약서x | F9: HD프랭크샤프트 가구 | G9: 여인표 | I9: 법인사업자 | L9: 8019000 | N9: =SUM(표1_6[[#This Row],[본 공사 금액]:[추가 공사 금액]]) -> 8019000 | O9: 1480000 | P9: 0.2 | U9: 견적서o
A10: 인테리어 도면 | B10: 웨딩홀 도면작업 | C10: 계약서x | D10: 계약서x | E10: 계약서x | F10: 인테리어 도면 | G10: 보다(PLUS) | L10: 3300000 | N10: =SUM(표1_6[[#This Row],[본 공사 금액]:[추가 공사 금액]]) -> 3300000 | O10: 1200000 | P10: 0.55
A11: ㈜MH에탄올 사무실 인테리어 | B11: MH에탄올 본관 2,3층 사무실 | C11: 45721 | D11: 45721 | E11: 45763 | F11: ㈜MH에탄올 사무실 인테리어 | G11: ㈜MH에탄올 | H11: 최동호 | I11: 법인사업자 | J11: 190111-0003563 | K11: 608-81-03800 | L11: 160413000 | M11: 8536000 | N11: =SUM(표1_6[[#This Row],[본 공사 금액]:[추가 공사 금액]]) -> 168949000 | O11: 55935688 | P11: 0.36 | Q11: 경남 창원시 마산회원구 내서읍 광려천남로 25,1층 | R11: 유지보수 | S11: 원도급 | T11: 055-231-0701
A12: 다구리 109번지 근린생활시설 신축공사 | B12: 구산면 카페 건축 | C12: 45723 | D12: 45733 | E12: 45822 | F12: 다구리 109번지 근린생활시설 신축공사 | G12: 민지현 | H12: 민지현 | I12: 개인 | J12: x | K12: 780901-2824441 | L12: 275000000 | M12: 12617000 | N12: =SUM(표1_6[[#This Row],[본 공사 금액]:[추가 공사 금액]]) -> 287617000 | O12: 17380423 | P12: 0.1 | Q12: 경남 창원시 마산합포구 진동면 다구리 109번지 | R12: 신설 | S12: 원도급 | T12: 010-9193-7870 | U12: 민지현 주민번호 82,500,000 82,500,000, 82,500,000 /,카페 도만 27,500,000,12,617,000원 발행
B13: 구산면 카페 철거 | C13: 계약서x | D13: 계약서x | E13: 계약서x | L13: 3300000 | N13: =SUM(표1_6[[#This Row],[본 공사 금액]:[추가 공사 금액]]) -> 3300000 | O13: 3300000 | P13: 1 | U13: 철거 빽마진
A14: 창원 키움에셋플레너 인테리어 | B14: 키움에셋플래너 | C14: 45736 | D14: 45737 | E14: 45750 | F14: 창원 키움에셋플레너 인테리어 | G14: 키움에셋플레너 주식회사 | H14: 조용학 | I14: 법인사업자 | J14: 110111-2776445 | K14: 211-87-33738 | L14: 40000000 | N14: =SUM(표1_6[[#This Row],[본 공사 금액]:[추가 공사 금액]]) -> 40000000 | O14: 10606044 | P14: 0.29 | Q14: 경남 창원시 의창구 팔용로 428,605(드림피아상가) | R14: 유지보수 | S14: 원도급 | T14: 010-7723-5954
A15: 보루(어반브릭스)인테리어 | B15: 보루 | C15: 45744 | D15: 45747 | E15: 45747 | F15: 보루(어반브릭스)인테리어 | G15: 보루 창원의창점 | H15: 이건중 | I15: 개인사업자 | J15: x | K15: 521-48-00794 | L15: 2530000 | N15: =SUM(표1_6[[#This Row],[본 공사 금액]:[추가 공사 금액]]) -> 2530000 | O15: 830000 | P15: 0.36 | Q15: 경상남도 창원시 의창구 중동중앙로 47,1층 1008호 | T15: 010-6410-3837 | U15: 부분 인테리어
A16: 인테리어 도면 | B16: 미테리어 | C16: 계약서x | D16: 계약서x | E16: 계약서x | F16: 인테리어 도면 | L16: 660000 | N16: =SUM(표1_6[[#This Row],[본 공사 금액]:[추가 공사 금액]]) -> 660000 | O16: 236363 | P16: 0.44
A17: 네일샵 인테리어 | B17: 밀양 네일샵 | C17: 45751 | D17: 45752 | E17: 45775 | F17: 네일샵 인테리어 | G17: 박소연 | H17: 박소연 | I17: 개인사업자 | L17: 16379000 | M17: 4510000 | N17: =SUM(표1_6[[#This Row],[본 공사 금액]:[추가 공사 금액]]) -> 20889000 | O17: 9722496 | P17: 0.51 | Q17: 경남 밀양시 내이동 770-2,1층 | S17: 원도급 | T17: 0106238-4532
A18: 네일샵 인테리어 | B18: 현동 네일샵 | C18: 45756 | D18: 45757 | E18: 45777 | F18: 네일샵 인테리어 | G18: 네일유니비 | H18: 조선윤 | I18: 개인사업자 | J18: x | K18: 394-50-01011 | L18: 21000000 | M18: 150000 | N18: =SUM(표1_6[[#This Row],[본 공사 금액]:[추가 공사 금액]]) -> 21150000 | O18: 8047766 | P18: 0.42 | Q18: 경남 창원시 마산합포구 현동 7길 22,1층 114호 | S18: 원도급 | T18: 010-9684-8587
A19: 숲칼프(두피탈모관리샵)인테리어 | B19: 함안 네일샵 | C19: 45760 | D19: 45762 | E19: 45777 | F19: 숲칼프(두피탈모관리샵)인테리어 | G19: 숲칼프 함안점 | H19: 조현영 | I19: 개인사업자 | J19: x | K19: 464-11-02682 | L19: 29000000 | N19: =SUM(표1_6[[#This Row],[본 공사 금액]:[추가 공사 금액]]) -> 29000000 | O19: 11657866 | P19: 0.44 | Q19: 경남 함안군 가야읍 성내북길 10,102호 | S19: 원도급 | T19: 010-3501-2715
A20: 셀포렙 라헨느 인테리어 | B20: 용호동(정우상가)뷰티샵 | C20: 45757 | D20: 45762 | E20: 45787 | F20: 셀포렙 라헨느 인테리어 | G20: 박미정 | I20: 개인사업자 | J20: x | K20: 686-37-01449 | L20: 39800000 | N20: =SUM(표1_6[[#This Row],[본 공사 금액]:[추가 공사 금액]]) -> 39800000 | O20: 10893394 | P20: 0.3 | Q20: 경남 창원시 성산구 원이대로 587,2층 4호 | S20: 원도급 | T20: 010-4617-3301
A21: 지엔티 가구 | B21: 지엔티 가구 | C21: 계약서x | D21: 계약서x | E21: 계약서x | F21: 지엔티 가구 | G21: 지엔티 | I21: 법인사업자 | L21: 396000 | N21: =SUM(표1_6[[#This Row],[본 공사 금액]:[추가 공사 금액]]) -> 396000 | O21: 74000 | P21: 0.21
A22: 지엔티 가구 | B22: 지엔티 가구 | C22: 계약서x | D22: 계약서x | E22: 계약서x | F22: 지엔티 가구 | G22: 지엔티 | I22: 법인사업자 | L22: 979000 | N22: =SUM(표1_6[[#This Row],[본 공사 금액]:[추가 공사 금액]]) -> 979000 | O22: 304000 | P22: 0.21
A23: 인테리어 도면 | B23: 디자인마산 | C23: 계약서x | D23: 계약서x | E23: 계약서x | F23: 인테리어 도면 | L23: 660000 | N23: =SUM(표1_6[[#This Row],[본 공사 금액]:[추가 공사 금액]]) -> 660000 | O23: 200000 | P23: 0.44
A24: 경남산소 사무실 리모델링 | B24: 경남산소 | C24: 45777 | D24: 45742 | E24: 45813 | F24: 경남산소 사무실 리모델링 | G24: 이종석 | H24: 이종석 | L24: 72000000 | M24: 5016000 | N24: =SUM(표1_6[[#This Row],[본 공사 금액]:[추가 공사 금액]]) -> 77016000 | O24: 23206242 | P24: 0.34
A25: 제일전자공업㈜ 전시실 인테리어 | B25: 진례 제일전자공업 | C25: 45792 | D25: 45803 | E25: 45853 | F25: 제일전자공업㈜ 전시실 인테리어 | G25: 제일전자공업㈜ | L25: 52800000 | M25: 6468000 | N25: =SUM(표1_6[[#This Row],[본 공사 금액]:[추가 공사 금액]]) -> 59268000 | O25: 18357259 | P25: 0.38
A26: 마산종말이 | B26: 합성동 이자카야 | C26: 45803 | D26: 45803 | E26: 45811 | F26: 마산종말이 | G26: 정민철 | H26: 정민철 | I26: 개인사업자 | K26: 160-12-02394 | L26: 2800000 | M26: 165000 | N26: =SUM(표1_6[[#This Row],[본 공사 금액]:[추가 공사 금액]]) -> 2965000 | O26: 1135181 | P26: 0.43
A27: 이우철한방누릉지삼계탕(진해점) | B27: 진해 누룽지삼계탕 | C27: 45818 | D27: 45823 | E27: 45858 | F27: 이우철한방누릉지삼계탕(진해점) | G27: 김성남 | H27: 김성남 | I27: 개인사업자 | K27: 584-71-00662 | L27: 83985000 | M27: 27500000 | N27: =SUM(표1_6[[#This Row],[본 공사 금액]:[추가 공사 금액]]) -> 111485000 | O27: 31356294 | P27: 0.31 | Q27: 경남 창원시 진해구 천자로 393 | R27: 유지보수 | S27: 원도급 | T27: 010-3857-0574
A28: 상남동 금다방 빙수 철거 | B28: 상남동 금다방 빙수 | C28: 계약서x | D28: 계약서x | E28: 계약서x | F28: 상남동 금다방 빙수 철거 | L28: 2700000 | N28: =SUM(표1_6[[#This Row],[본 공사 금액]:[추가 공사 금액]]) -> 2700000 | O28: 760908 | P28: 0.31
A29: 이홍열법률사무소 인테리어 | B29: 이홍열법률사무소 | C29: 45831 | D29: 45831 | E29: 45861 | F29: 이홍열법률사무소 인테리어 | G29: 법무법인 시그널 | H29: 이홍열 | I29: 개인사업자 | K29: 386-88-03326 | L29: 53119000 | M29: 15114000 | N29: =SUM(표1_6[[#This Row],[본 공사 금액]:[추가 공사 금액]]) -> 68233000 | O29: 12086038 | P29: 0.26 | Q29: 경상남도 창원시 성산구 창이대로 689번길 4-4,301호 | R29: 유지보수 | S29: 원도급 | T29: 010-2997-2019
A30: 도만 카페 인테리어 | B30: 구산면 도만 카페 | C30: 45828 | D30: 도만 | E30: 45869 | F30: 도만 카페 인테리어 | G30: 민지현 | H30: 민지현 | I30: 개인 | K30: 780901-2824441 | L30: 178000000 | N30: =SUM(표1_6[[#This Row],[본 공사 금액]:[추가 공사 금액]]) -> 178000000 | O30: 60816168 | P30: 0.38 | Q30: 경남 창원시 마산합포구 진동면 다구리 109번지 | R30: 유지보수 | S30: 원도급 | T30: 010-9193-7870 | U30: 카페 도만 사업자로 세금계산서 발행
A31: 스포츠가치센터 이용자 휴게공간 및 흡연부스 공사 | B31: 진주스포츠센터 | C31: 45845 | E31: 45901 | F31: 스포츠가치센터 이용자 휴게공간 및 흡연부스 공사 | G31: 서울올림픽기념국민체육진흥공단 | H31: 최형도 | I31: 공공기간 | L31: 36905000 | N31: =SUM(표1_6[[#This Row],[본 공사 금액]:[추가 공사 금액]]) -> 36905000 | O31: 17411938 | P31: 0.53 | Q31: 경상남도 진주시 내동면 삼계로 360, 스포츠가치센터 | R31: 유지보수 | S31: 원도급 | T31: 02-410-1222 | U31: 나라장터 입찰 계약<승인요청함
A32: 디에프 | B32: 팔용동 사진관 | C32: 45839 | D32: 45842 | E32: 45852 | F32: 디에프 | G32: 이강우 | H32: 디에프 | I32: 개인사업자 | K32: 418-54-00368 | L32: 7752566 | N32: =SUM(표1_6[[#This Row],[본 공사 금액]:[추가 공사 금액]]) -> 7752566 | O32: 3592613 | P32: 0.51 | Q32: 경남 창원시 의창구 의창대로 180번길 2,1층 | R32: 유지보수 | S32: 원도급 | T32: 010-5295-6035
A33: 이우철 누수보수작업 | B33: 이우철 누수보수작업 | C33: 계약서x | D33: 계약서x | E33: 계약서x | F33: 이우철 누수보수작업 | L33: 2838000 | N33: =SUM(표1_6[[#This Row],[본 공사 금액]:[추가 공사 금액]]) -> 2838000 | O33: 2838000 | P33: 1
A34: 인테리어 도면 | B34: 디자인마산 | C34: 계약서x | D34: 계약서x | E34: 계약서x | F34: 인테리어 도면 | L34: 990000 | N34: =SUM(표1_6[[#This Row],[본 공사 금액]:[추가 공사 금액]]) -> 990000 | O34: 405000 | P34: 0.45
A35: 인테리어 도면 | B35: 주식회사 좋은 | C35: 계약서x | D35: 계약서x | E35: 계약서x | F35: 인테리어 도면 | L35: 440000 | N35: =SUM(표1_6[[#This Row],[본 공사 금액]:[추가 공사 금액]]) -> 440000 | O35: 440000 | P35: 1
A36: 주식회사 세영테크놀러지 | B36: 세영 테크노벨리 | C36: 45842 | D36: 45843 | E36: 45847 | F36: 주식회사 세영테크놀러지 | I36: 법인사업자 | J36: 194211-0250407 | K36: 596-87-00268 | L36: 6127000 | N36: =SUM(표1_6[[#This Row],[본 공사 금액]:[추가 공사 금액]]) -> 6127000 | O36: 2298132 | P36: 0.41 | Q36: 경남 창원시 성산구 창곡로 108번길 15-20(신촌동) | R36: 유지보수 | S36: 원도급 | T36: 010-3412-7005
A37: HD현대마린엔진 생활관 탈의실 개선 및 가구 교체 공사 | B37: 현대마린엔진 | C37: 45868 | D37: 45866 | E37: 45879 | F37: HD현대마린엔진 생활관 탈의실 개선 및 가구 교체 공사 | G37: HD현대마린엔진 | H37: 강 영 | I37: 법인사업자 | J37: 194211-0048381 | K37: 609-81-48213 | L37: 94050000 | M37: 517000 | N37: =SUM(표1_6[[#This Row],[본 공사 금액]:[추가 공사 금액]]) -> 94567000 | O37: 26203955 | P37: 0.31 | Q37: 경상남도 창원시 성산구 적현로 222(신촌동) | R37: 유지보수 | S37: 원도급 | T37: 055-240-0200
A38: 중동 미용실 인테리어 | B38: 중동 미용실 | C38: 45861 | D38: 45861 | E38: 45890 | F38: 중동 미용실 인테리어 | G38: 안예나 | H38: 안예나 | I38: 개인 | L38: 18280000 | M38: 165000 | N38: =SUM(표1_6[[#This Row],[본 공사 금액]:[추가 공사 금액]]) -> 18445000 | O38: 26203955 | P38: 0.44
A39: 2025 PNU 펜토미노 교육과정 원예생명과학과 강의실 환경개선 공사 | B39: 부산대학교 생명자원과학대학 원예학과 | C39: 45866 | D39: 45867 | E39: 45897 | F39: 2025 PNU 펜토미노 교육과정 원예생명과학과 강의실 환경개선 공사 | G39: 부산대학교 | H39: 최재원 | I39: 법인사업자 | K39: 621-83-00678 | L39: 33500000 | N39: =SUM(표1_6[[#This Row],[본 공사 금액]:[추가 공사 금액]]) -> 33500000 | O39: 16114218 | P39: 0.53 | Q39: 경남 밀양시 삼랑진읍 삼랑진로 1268-50 부산대학교 밀양캠퍼스 생명자원과학관 3434호 | R39: 유지보수 | S39: 원도급 | T39: 055-350-5174
A40: 인테리어 도면 | B40: 한국산업단지공단 | C40: 계약서x | D40: 계약서x | E40: 계약서x | F40: 인테리어 도면 | L40: 1782000 | N40: =SUM(표1_6[[#This Row],[본 공사 금액]:[추가 공사 금액]]) -> 1782000 | O40: 1782000 | P40: 1
...

Sheet 법인 2025 발송현황
A1: 공사명 | B1: 분류 | D1: 전화번호 | E1: 현장명 | F1: 계약일 | G1: 시작일 | H1: 준공일 | I1: 공사명 | J1: 발주자 명 | K1: 대표자 명 | L1: 구분 | M1: 법인등록번호 | N1: 사업자등록증(주민등록증) | O1: 본 공사 금액 | P1: 추가 공사 금액 | Q1: 합계 | R1: 순이익 금액 | S1: % | T1: 현장 주소 | U1: 공사유형 | V1: 도급 종류 | W1: 전화번호 | X1: 비고1
A2: 주식회사 세영테크놀러지 | B2: 우편 | C2: 받으러 오라함 | D2: 010-3412-7005 | E2: 세영 테크노벨리 | F2: 45842 | G2: 45843 | H2: 45847 | I2: 주식회사 세영테크놀러지 | L2: 법인사업자 | M2: 194211-0250407 | N2: 596-87-00268 | O2: 6127000 | Q2: =SUM(표1_6[[#This Row],[본 공사 금액]:[추가 공사 금액]]) -> 33220000 | R2: 2298132 | S2: 0.41 | T2: 경남 창원시 성산구 창곡로 108번길 15-20(신촌동) | U2: 유지보수 | V2: 원도급 | W2: 010-3412-7005
A3: 제일전자공업㈜ 전시실 인테리어 | B3: 우편 | D3: 010-2978-3493 | E3: 진례 제일전자공업 | F3: 45792 | G3: 45803 | H3: 45853 | I3: 제일전자공업㈜ 전시실 인테리어 | J3: 제일전자공업㈜ | O3: 52800000 | P3: 6468000 | Q3: =SUM(표1_6[[#This Row],[본 공사 금액]:[추가 공사 금액]]) -> 27335000 | R3: 18357259 | S3: 0.38 | T3: 경남 김해시 진례면 고모로216번길 59-5
A4: 창원 키움에셋플레너 인테리어 | B4: 우편 | C4: 출장중 불가 | D4: 010-7723-5954 | E4: 키움에셋플래너 | F4: 45736 | G4: 45737 | H4: 45750 | I4: 창원 키움에셋플레너 인테리어 | J4: 키움에셋플레너 주식회사 | K4: 조용학 | L4: 법인사업자 | M4: 110111-2776445 | N4: 211-87-33738 | O4: 40000000 | Q4: =SUM(표1_6[[#This Row],[본 공사 금액]:[추가 공사 금액]]) -> 32500000 | R4: 10606044 | S4: 0.29 | T4: 경남 창원시 의창구 팔용로 428,605(드림피아상가) | U4: 유지보수 | V4: 원도급 | W4: 010-7723-5954 | X4: 서울시 강남구 명동대로 424,5층 키움에셋플레너 경영지원팀 이준대리

Sheet 법인 2024
A2: 2024년
B3: 현장명 | C3: 시작일 | D3: 준공일 | E3: 공사명 | F3: 고객 | G3: 금액 | H3: 순이익 | I3: 비고
B4: 소답동미용실 | C4: 45299 | D4: 45327 | E4: 소답동 미용실 인테리어 | F4: 이한솔 | G4: 9830000
B5: 교방동 누리학원 | C5: 45309 | D5: 45337 | E5: 교방동 누리학원 인테리어 공사 | F5: 이누리 | G5: 52448000
B6: 경남대 미래라이프대학 | C6: 45315 | D6: 45343 | E6: 경남대학교 평생교육관 미래라이프대학 강의실 및 실습실 구축공사 | F6: 경남대학교 총장 | G6: 83330187
B7: 소답동카페 | C7: 45355 | D7: 45374 | E7: 소답동 카페 인테리어 | F7: 김혜진 | G7: 23400000
B8: 엠에스이 회의실 | C8: 45355 | D8: 45368 | E8: 엠에스이 회의실 인테리어 | F8: 엠에스이주식회사 | G8: 17952000
B9: 진영HNS 로비 | C9: 45355 | D9: 45386 | E9: 진영HNS로비/접견실 인테리어 | F9: ㈜진영에이치앤에스 | G9: 75900000
B10: 두산위브앨리스 | C10: 45357 | D10: 45374 | E10: 앨리스 인테리어 공사 | F10: 박연주 | G10: 16192000
B11: 더베이커스 | C11: 45363 | D11: 45390 | E11: 더 베이커스 인테리어 | F11: 홍성희 | G11: 18600000
B12: 양덕동 미용실 | C12: 45369 | D12: 45387 | E12: 헤어샾 인테리어 공사 | F12: 정혜진 | G12: 17600000
B13: 진해삼서영어 | C13: 45376 | D13: 45390 | E13: 진해삼성영어학원 인테리어 | F13: 정다정 | G13: 22221100
B14: 더강해진수학교습소 | C14: 45387 | D14: 45402 | E14: 더강해진수학교습소 인테리어 | F14: 더강해진수학교습소 | G14: 15300000
B15: 삼일기술단 | C15: 45390 | D15: 45399 | E15: 주식회사 삼일기술단 인테리어 | F15: 김미란 | G15: 7316000
B16: 모드텍 | C16: 45413 | D16: 45436 | E16: 주식회사 모드텍 인테리어 공사 | F16: 이상재 | G16: 4136000
B17: 착한미용실 | C17: 45429 | D17: 45465 | E17: 착한미용실 인테리어 | F17: 김보연 | G17: 80487000 | H17: 0.1
B18: 에스지정공 | C18: 45435 | D18: 45440 | E18: 주식회사 에스지 정공 | F18: 박현민 | G18: 6000000 | H18: 0.28
B19: 낙동강유역환경청 | C19: 45437 | D19: 45448 | E19: 낙동강유역환경청 1층 인테리어 공사 | F19: 낙동강유역환경청 | G19: 18877000
B20: 화연제과 | C20: 45451 | D20: 45467 | E20: 화연제과 반송점 인테리어 공사 | F20: 심유진 | G20: 12606000 | H20: 0.25
B21: JD505 LT수학 | C21: 45453 | D21: 45475 | E21: JD윙스 505호 인테리어 공사 | F21: 정윤정 | G21: 43703000 | H21: 0.32
B22: JD504 리드인 | C22: 45453 | D22: 45475 | E22: JD윙스 504호 인테리어 공사 | F22: 고은영 | G22: 31625000 | H22: 0.27
B23: 낙동강2층 | C23: 45458 | D23: 45460 | E23: 낙동강유역환경청 2층 부분 인테리어 공사 | F23: 낙동강유역환경청 | G23: 1826000
B24: 북면 학원인테리어 | C24: 45460 | D24: 45479 | E24: 창원 북면 학원인테리어 | F24: 임성진 | G24: 24800000
B25: SK 615호 | C25: 45471 | D25: 45492 | E25: SK테크노파크 618호 사무실인테리어 | F25: 조우영 | G25: 27500000
B26: 샌드빅회의실 | C26: 45471 | D26: 45476 | E26: 창원 한국샌드빅㈜회의실 환경개선공사 | F26: 한국샌드빅㈜ | G26: 2255000
B27: 손길헤어 | C27: 45476 | D27: 45495 | E27: 손길헤어 인테리어 공사 | F27: 강송이 | G27: 13695000
B28: 미래환경 | C28: 45481 | D28: 45504 | E28: 미래환경㈜인테리어공사 | F28: 김일 | G28: 22500000
B29: 어반브릭스12층 | C29: 45491 | D29: 45503 | E29: 어반브릭스12층 | F29: 서유진 | G29: 8700000
B30: 휴텍스코리아 | C30: 45499 | D30: 45504 | E30: 휴텍스 코리아 | F30: 한수교 | G30: 3685000
B31: 감계 푸르지오 교습소 | C31: 45502 | D31: 45514 | E31: 창원 북면 감계 푸르지오 교습소인테리어 | F31: 박명민 | G31: 16470000
B32: 지엔티 인테리어 | C32: 45503 | D32: 45503 | E32: ㈜지엔티 인테리어 공사 | F32: ㈜지엔티 | G32: 440000
B33: 산호동 국밥집 | C33: 45510 | D33: 45512 | E33: 창원 마산합포구 산호남로 17-1 철거 | F33: JM건축인테리어 | G33: 2684000
B34: 청춘 푸줏간 | C34: 45511 | D34: 45538 | E34: 청춘푸줏간 인테리어 | F34: 유주환 | G34: 16400000
B35: 스포츠가치센터 디자인 | C35: 45516 | D35: 45531 | E35: 진주스포츠가치센터 대강당 환경개선공사 | F35: 조현재 | G35: 2800000
B36: 힐스테이트미용실 | C36: 45518 | D36: 45535 | E36: 창원 힐스테이트 미용실 인테리어 | F36: 구년근 | G36: 22200000 | H36: 0.28
B37: 봉덕소 세영수학교습소 | C37: 45529 | D37: 45542 | E37: 세영수학교습소 인테리어 | F37: 정혜선 | G37: 12529000 | H37: 0.58
B38: 스포츠가치센터 유스텔 디자인 | C38: 45534 | D38: 45545
B39: 아름드리숲상담센터 | C39: 45538 | D39: 45549 | E39: 아름드리숲상담센터 인테리어 | F39: 김유진 | G39: 14872000 | H39: 0.46
B40: HK창원 | C40: 45539 | D40: 45559 | E40: 에이치케이금융파트너스 경남사업단 인테리어 및 원상복구 | F40: 에이치케이금융파트너스 대표이사 신용준 | G40: 29799000 | H40: 0.36
B41: 문소영 | C41: 45572 | D41: 45591 | E41: 문소영 수학관리학원인테리어 | F41: 문소영 | G41: 31999000 | H41: 0.29
...

Sheet 법인2023
A2: 2023년
B3: 현장명 | C3: 시작일 | D3: 준공일 | E3: 공사명 | F3: 고객 | G3: 금액 | H3: 사업자구분
B4: 제니스코딩 교습소 | C4: 44928 | D4: 44942 | E4: 재니스코딩 교습소 인테리어 | F4: 이지연 | G4: 11457600 | H4: 개인
B5: 유니시티1단지 수학교습소 | C5: 44958 | D5: 44975 | E5: 유니시티1단지 수학교습소 | F5: 김언진 | G5: 15279000 | H5: 개인
B6: 고성이발소 | C6: 44973 | D6: 44993 | E6: 고성이발소 인테리어 | F6: 한나경 | G6: 21213000 | H6: 개인
B7: 코아텍시스템즈 | C7: 44982 | D7: 45003 | E7: ㈜코아텍시스템즈 | F7: ㈜코아텍시스템즈 | G7: 35500000 | H7: 개인
B8: 창녕바당돌담 | C8: 45000 | D8: 45031 | E8: 창녕 바당돌담 인테리어 | F8: 최필호 | G8: 137800000 | H8: 개인
B9: 가로수길 바버샵 | C9: 45008 | D9: 45033 | E9: 가로수길 바버샾 | F9: 하경호 | G9: 21600000 | H9: 개인
B10: 아모레퍼시픽 | C10: 45008 | D10: 45039 | E10: 아모레퍼시픽 인테리어 | F10: 신현웅 | G10: 62450000 | H10: 개인
B11: 신화철강 샘플하우스 | C11: 45016 | D11: 45028 | E11: 신화철강 샘플하우스 인테리어 | F11: ㈜STEEL BANK | G11: 9029900 | H11: 개인
B12: 그롭코리아 회의실 | C12: 45035 | D12: 45049 | E12: 그롭코리아 회의실 인테리어 | F12: 그롭코리아 주식회사 | G12: 12881000 | H12: 개인
B13: 지엔티인테리어 | C13: 45040 | D13: 45086 | E13: ㈜지엔티 인테리어 공사 | F13: ㈜지엔티 | G13: 270000000 | H13: 개인
B14: 창녕미용실 | C14: 45040 | D14: 45071 | E14: 창녕미용실 인테리어 공사 | F14: 하재령 | G14: 35379000 | H14: 개인
B15: 청도면 요고리농막 | C15: 45050 | D15: 45076 | E15: 청도면 요고리 농막 | F15: 황용순 | G15: 37000000 | H15: 개인
... B25: 보원산업2층 | C25: 45177 | D25: 45196 | E25: 보원산업 2층 사무실공사 | F25: ㈜보원산업 | G25: 50000000 | H25: 법인
B26: 셰플러코리아 구내식당 | C26: 45191 | D26: 45224
B27: 함안군수실 | C27: 45225 | D27: 45240
B28: 혜성정밀 | C28: 45225 | D28: 45240 | E28: 혜성정밀 사무실 인테리어 | F28: 이을식 | G28: 23320000 | H28: 법인
B29: 야마자키마작 사무실 | C29: 45231 | D29: 45250 | E29: 창원 야마자키마작 사무실 인테리어 | F29: 한국야마자키마작㈜ | G29: 62000000 | H29: 법인
B30: 제주낙천리 | C30: 45231 | D30: 45280 | E30: 제주 낙천리 목조주택 기초 및 토목공사 | F30: 이영희 | G30: 7800000 | H30: 법인
B31: DS동산 | C31: 45233 | D31: 45250 | E31: DS동산㈜사무동 리모델링 공사 | F31: DS동산㈜ | G31: 48540800 | H31: 법인
B32: 헥사곤 | C32: 45237 | D32: 45265 | E32: 헥사곤 사무실인테리어 공사 | F32: 한국헥사곤메트롤리지 유한회사 | G32: 75688800 | H32: 법인
B33: 진영HNS화장실 | C33: 45239 | D33: 45293 | E33: 진영HNS화장실 인테리어공사 | F33: ㈜진영에이치앤에스 | G33: 26400000 | H33: 법인
B34: 진영HNS경비동 | C34: 45240 | D34: 45260 | E34: 진영HNS경비동 철거 | F34: ㈜진영에이치앤에스 | G34: 10450000 | H34: 법인
B35: 요리수수학교습소 | C35: 45247 | D35: 45288 | E35: 요리수수학교습소 인테리어 | F35: 요리수수학학원 | G35: 14249400 | H35: 법인
B36: 보원산업추가공사 | C36: 45250 | D36: 45260 | E36: 보원산업 추가공사 | F36: 보원산업 | G36: 8062000 | H36: 개인
B37: 위딘 회의실 | C37: 45250 | D37: 45268 | E37: 주식회사 위딘 4층 회의실 인테리어작업 | F37: 주식회사 위딘 | G37: 30800000 | H37: 법인
B38: 지안SMP | C38: 45272 | D38: 45288 | E38: 지안SMP인테리어 공사 | F38: 지안SMP아카데미 | G38: 21600000 | H38: 법인
B40: 합계 | G40: =SUM(G4:G39) -> 1337279500

Sheet 2022년
A2: 2022년
B3: 현장명 | C3: 시작일 | D3: 준공일 | E3: 공사명 | F3: 고객명 | G3: 금액
B4: 마린애시앙 학원 | C4: 44571 | D4: 44590 | E4: 마린애시앙학원 | F4: 윤정남 | G4: 17399200
B5: 신월동 배달음식점 | C5: 44571 | D5: 44576 | E5: 신월동 배달음식점 | F5: 김지욱 | G5: 8500000
B6: 김해테일러샵 | C6: 44580 | D6: 44610 | E6: 김해 테일러샵 | F6: 권소영 | G6: 29000000
B7: 가음정 미용실 | C7: 44599 | D7: 44618 | E7: 가음정미용실 | F7: 이은주 | G7: 18473000
B8: 본파이어베이프 | C8: 44602 | D8: 44615 | E8: 본파이어베이프 마산 | F8: 진영균 | G8: 18292500
B9: 일진사무동 | C9: 44613 | D9: 44625 | E9: 일진G&S㈜사무동 리모델링 | F9: 일진G&S㈜ | G9: 35400000
B10: 큰나래 당리동 | C10: 44621 | D10: 44659 | E10: 큰나래학원(당리동) | F10: 김양우 | G10: 42770000
B11: 밀양 청학리 농막 | C11: 44623 | D11: 44643 | E11: 밀양청학리농막리모델링 | F11: 김은하 | G11: 22470000
B12: 합포구 회원동북로52 | C12: 44632 | D12: 44646 | E12: 마산 합포구 회원동북로52 1층 | F12: 김담희 | G12: 12693500
B13: 대낭숲 북면 | C13: 44634 | D13: 44667 | E13: 대낭숲리모델링 | F13: 이미리 | G13: 76767000
B14: 합성동 디스튜디오 뷰티아카데미 | C14: 44641 | D14: 44666 | E14: 합성동 디스튜디오 뷰티아카데미 | F14: 이서율 | G14: 34718000
B15: 한일타운 리모델링 | C15: 44648 | D15: 44673 | E15: 한일타운 리모델링 | F15: 정재훈 | G15: 35000000
... B38: 창녕 사회복지타운 카운터교체 | C38: 44917 | D38: 44917 | E38: 창녕 사회복지타운 카운터 교체 | F38: 이량하 | G38: 2470000
B40: 합계 | G40: =SUM(G4:G39) -> 1106013580

Sheet 2021년
A2: 2021년
B3: 현장명 | C3: 시작일 | D3: 준공일 | E3: 공사명 | F3: 고객명 | G3: 금액
B4: 대성 프리존텔 402호 | C4: 44218 | D4: 44225 | E4: 대성 프리존텔 402호 | F4: 양혜진 | G4: 4000000
B5: 진해우림필유 미용실 | C5: 44223 | D5: 44249 | E5: 진해우림필유상가 미용실 | F5: 이승훈 | G5: 13379300
B6: 대한토목설계사무소 | C6: 44247 | D6: 44265 | E6: 대한토목설계사무소 | F6: 최희철 | G6: 24400000
B7: 명성수학교습소 | C7: 44263 | D7: 44279 | E7: 명성수학교습소 | F7: 박진호 | G7: 20000000
B8: 떡메치는 조서방 | C8: 44281 | D8: 44305 | E8: 떡메치는조서방 | F8: 조현태 | G8: 27730000
B9: 금돌부동산중개 | C9: 44328 | D9: 44336 | E9: 금돌부동산중개 | F9: 이지윤 | G9: 10010000
B10: 북면떡볶이 | C10: 44333 | D10: 44352 | E10: 북면떡볶이 | F10: 오희은 | G10: 13800000
B11: 북면과학학원 | C11: 44344 | D11: 44362 | E11: 북면과학학원 | F11: 박창환 | G11: 23100000
B12: 비앤지사원아파트 | C12: 44396 | D12: 44403 | E12: 비앤지사원아파트506호 | F12: 박지성 | G12: 5164500
B13: 제이엠모터스사무실 | C13: 44399 | D13: 44428 | E13: 사무실리모델링 | F13: 주식회사 제이엠모터스펌프(이영훈) | G13: 77500000
B14: 어반브릭스 오피스동학원 | C14: 44431 | D14: 44469 | E14: 어반브릭스 오피스동 학원 | F14: 김경민 | G14: 65000000
B15: 제이엠모터스 공장동판넬 | C15: 44454 | D15: 44469 | E15: 공장동 판넬공사 | F15: 주식회사 제이엠모터스펌프(이영훈) | G15: 6000000
... B25: 월영동 미용실 | C25: 44550 | D25: 44588 | E25: 월영동 미용실 | F25: 조은샘 | G25: 17053600
B27: 합계 | G27: =SUM(G4:G26) -> 690887250

Sheet 2020년
A1: 2021년
B2: 현장명 | C2: 시작일 | D2: 준공일 | E2: 공사명 | F2: 고객명 | G2: 금액
B3: 장미공원2층 | C3: 43880 | D3: 43886 | E3: 성산구 동산로 115, 장미상가 2층 | F3: 박원규 | G3: 4570000
B4: 일동아파트 12동 207호 | C4: 43880 | D4: 43887 | E4: 성산구 용호동 일동아파트 12동 207호 | F4: 반초록 | G4: 4650000
B5: 오부리또 | C5: 43886 | D5: 43903 | E5: 오 부리또 | F5: 윤선화 | G5: 13990000
B6: 도계한마음코아 | C6: 43909 | D6: 43909 | E6: 도계동 한마음코아 102동 301호 | F6: 현인숙 | G6: 10100000
B7: 용호동 카페 | C7: 43980 | D7: 44000 | E7: 용호동 카페 | F7: 조민희 | G7: 19690000
B8: 대방동 덕산2차 | C8: 44046 | D8: 44071 | E8: 성산구 대방동 덕산 2차 207동 1704호 | F8: 김민건 | G8: 29425000
B9: 샐러디 상남점 | C9: 44058 | D9: 44071 | E9: 샐러디 창원상남점 | F9: 조호성 | G9: 16170000
B10: 마산내서스튜디오 | C10: 44176 | D10: 44195 | E10: 마산내서스튜디오 | F10: 손주현 | G10: 27852000
B11: 메트로미용실 | C11: 44186 | D11: 44214 | E11: 메트로미용실 | F11: 박재만 | G11: 38000000
B12: 곽두리 쪽갈비 | C12: 44194 | D12: 44221 | E12: 곽두리 쪽갈비 | F12: 차욱진 | G12: 34400000
B13: 미코미용실 | C13: 44199 | D13: 44222 | E13: 미코미용실 | F13: 김양경 | G13: 19800000
B16: 합계 | G16: =SUM(G3:G15) -> 218647000
